Workbook

Sheet BẢN TÍNH GIÁ THÀNH
A1: BẢNG CÔNG THỨC TÍNH GIÁ GIA CÔNG NHÔM MAXPRO NHẬT BẢN
A2: STT | B2: SẢN PHẨM | F2: DIỆN TÍCH | G2: NHÔM | H2: VẬT TƯ | I2: CÔNG THỢ | J2: CHI PHÍ CỐ ĐỊNH | K2: CHI PHÍ QUẢNG CÁO | L2: CHI PHÍ KHÁC | M2: TỔNG CHI PHÍ | N2: TỔNG VẬT TƯ | O2: GIÁ BÁN HOÀ VỐN | P2: DOANH THU HOÀ VỐN | Q2: GIÁ BÁN LỢI NHUẬN | R2: DOANH THU LỢI NHUẬN | S2: THUẾ ( VAT ) | T2: LỢI NHUẬN SAU CÙNG | U2: TRUNG BÌNH
B3: NHÔM XINGFA QUẢNG ĐÔNG | D3: HỆ NHÔM | E3: ĐỘ DÀY | F3: m2 | G3: VẬT TƯ | H3: 1M2 | I3: 108000 | J3: 44000 | K3: 24000 | L3: 7000 | M3: =SUM(I3:L3) -> 183000 | N3: CHI PHÍ | O3: M2 | P3: M2 | Q3: M2 | R3: M2 | S3: 0.02 | T3: LỢI NHUẬN SAU CÙNG
A4: 1 | B4: CỬA ĐI 1 CÁNH MỞ QUAY | D4: 55 | E4: 2,0mm | F4: ='ĐI QUAY 1 CÁNH'!F6/1000 -> 2.08304 | G4: ='ĐI QUAY 1 CÁNH'!V19 -> 3753166 | H4: =G4/F4 -> 1801773.4 | I4: =$I$3*F4 -> 224968.32 | J4: =$J$3*F4 -> 91653.76 | K4: =$K$3*F4 -> 49992.96 | L4: =$L$3*F4 -> 14581.28 | M4: =SUM(I4:L4) -> 381196.32 | N4: =SUM(I4:L4)+G4 -> 4134362.3 | O4: =P4/F4 -> 2025278.9 | P4: =N4/(1-$S$3) -> 4218737.1 | Q4: =R4/F4 -> 2227806.8 | R4: =P4*1.1 -> 4640610.8 | S4: =R4*$S$3 -> 92812.215 | T4: =R4-N4-S4 -> 413436.23 | U4: =SUM(Q4:Q6)/3 -> 2308011.8
A5: =A4+1 -> 2 | B5: CỬA ĐI 2 CÁNH MỞ QUAY | D5: 55 | E5: 2,0mm | F5: ='ĐI QUAY 2 CÁNH'!F6/1000 -> 3.6 | G5: ='ĐI QUAY 2 CÁNH'!V21 -> 6965012.2 | H5: =G5/F5 -> 1934725.6 | I5: =$I$3*F5 -> 388800 | J5: =$J$3*F5 -> 158400 | K5: =$K$3*F5 -> 86400 | L5: =$L$3*F5 -> 25200 | M5: =SUM(I5:L5) -> 658800 | N5: =SUM(I5:L5)+G5 -> 7623812.2 | O5: =P5/F5 -> 2160944.5 | P5: =N5/(1-$S$3) -> 7779400.2 | Q5: =R5/F5 -> 2377039 | R5: =P5*1.1 -> 8557340.3 | S5: =R5*$S$3 -> 171146.81 | T5: =R5-N5-S5 -> 762381.22
A6: =A5+1 -> 3 | B6: CỬA ĐI 4 CÁNH MỞ QUAY | D6: 55 | E6: 2,0mm | F6: ='ĐI QUAY 4 CÁNH'!F6/1000 -> 6.9795 | G6: ='ĐI QUAY 4 CÁNH'!V21 -> 13143704 | H6: =G6/F6 -> 1883187.1 | I6: =$I$3*F6 -> 753786 | J6: =$J$3*F6 -> 307098 | K6: =$K$3*F6 -> 167508 | L6: =$L$3*F6 -> 48856.5 | M6: =SUM(I6:L6) -> 1277248.5 | N6: =SUM(I6:L6)+G6 -> 14420953 | O6: =P6/F6 -> 2108354.2 | P6: =N6/(1-$S$3) -> 14715258 | Q6: =R6/F6 -> 2319189.6 | R6: =P6*1.1 -> 16186784 | S6: =R6*$S$3 -> 323735.67 | T6: =R6-N6-S6 -> 1442095.3
A7: =A6+1 -> 4 | B7: CỬA SỔ 1 CÁNH MỞ QUAY | D7: 55 | E7: 1,4mm | F7: ='SỔ QUAY 1CÁNH'!F6/1000 -> 1.05 | G7: ='SỔ QUAY 1CÁNH'!V17 -> 1997308.1 | H7: =G7/F7 -> 1902198.2 | I7: =$I$3*F7 -> 113400 | J7: =$J$3*F7 -> 46200 | K7: =$K$3*F7 -> 25200 | L7: =$L$3*F7 -> 7350 | M7: =SUM(I7:L7) -> 192150 | N7: =SUM(I7:L7)+G7 -> 2189458.1 | O7: =P7/F7 -> 2127753.3 | P7: =N7/(1-$S$3) -> 2234140.9 | Q7: =R7/F7 -> 2340528.6 | R7: =P7*1.1 -> 2457555 | S7: =R7*$S$3 -> 49151.101 | T7: =R7-N7-S7 -> 218945.81 | U7: =SUM(Q7:Q10)/4 -> 2132266.5
A8: =A7+1 -> 5 | B8: CỬA SỔ 2 CÁNH MỞ QUAY | D8: 55 | E8: 1,4mm | F8: ='Sổ QUAY 2 CÁNH'!F6/1000 -> 1.8 | G8: ='Sổ QUAY 2 CÁNH'!V19 -> 2946275.3 | H8: =G8/F8 -> 1636819.6 | I8: =$I$3*F8 -> 194400 | J8: =$J$3*F8 -> 79200 | K8: =$K$3*F8 -> 43200 | L8: =$L$3*F8 -> 12600 | M8: =SUM(I8:L8) -> 329400 | N8: =SUM(I8:L8)+G8 -> 3275675.3 | O8: =P8/F8 -> 1856958.8 | P8: =N8/(1-$S$3) -> 3342525.8 | Q8: =R8/F8 -> 2042654.7 | R8: =P8*1.1 -> 3676778.4 | S8: =R8*$S$3 -> 73535.568 | T8: =R8-N8-S8 -> 327567.53
A9: =A8+1 -> 6 | B9: CỬA SỔ 3 CÁNH MỞ QUAY | D9: 55 | E9: 1,4mm | F9: ='Sổ QUAY 3 CÁNH -Đố tĩnh'!F6/1000 -> 2.4 | G9: ='Sổ QUAY 3 CÁNH -Đố tĩnh'!V18 -> 4123144.3 | H9: =G9/F9 -> 1717976.8 | I9: =$I$3*F9 -> 259200 | J9: =$J$3*F9 -> 105600 | K9: =$K$3*F9 -> 57600 | L9: =$L$3*F9 -> 16800 | M9: =SUM(I9:L9) -> 439200 | N9: =SUM(I9:L9)+G9 -> 4562344.3 | O9: =P9/F9 -> 1939772.2 | P9: =N9/(1-$S$3) -> 4655453.4 | Q9: =R9/F9 -> 2133749.5 | R9: =P9*1.1 -> 5120998.7 | S9: =R9*$S$3 -> 102419.97 | T9: =R9-N9-S9 -> 456234.43
A10: =A9+1 -> 7 | B10: CỬA SỔ 4 CÁNH MỞ QUAY | D10: 55 | E10: 1,4mm | F10: ='Sổ QUAY 4 CÁNH đố tĩnh'!F6/1000 -> 3.6 | G10: ='Sổ QUAY 4 CÁNH đố tĩnh'!V20 -> 5794660.6 | H10: =G10/F10 -> 1609627.9 | I10: =$I$3*F10 -> 388800 | J10: =$J$3*F10 -> 158400 | K10: =$K$3*F10 -> 86400 | L10: =$L$3*F10 -> 25200 | M10: =SUM(I10:L10) -> 658800 | N10: =SUM(I10:L10)+G10 -> 6453460.6 | O10: =P10/F10 -> 1829212.2 | P10: =N10/(1-$S$3) -> 6585163.9 | Q10: =R10/F10 -> 2012133.4 | R10: =P10*1.1 -> 7243680.2 | S10: =R10*$S$3 -> 144873.6 | T10: =R10-N10-S10 -> 645346.06
A11: =A10+1 -> 8 | B11: VÁCH KÍNH | D11: 55 | E11: 1,4mm | F11: ='VÁCH KÍNH 55'!F6/1000 -> 0.40138 | G11: ='VÁCH KÍNH 55'!V15 -> 573100.48 | H11: =G11/F11 -> 1427825.2 | I11: =$I$3*F11 -> 43349.04 | J11: =$J$3*F11 -> 17660.72 | K11: =$K$3*F11 -> 9633.12 | L11: =$L$3*F11 -> 2809.66 | M11: =SUM(I11:L11) -> 73452.54 | N11: =SUM(I11:L11)+G11 -> 646553.02 | O11: =P11/F11 -> 1643699.2 | P11: =N11/(1-$S$3) -> 659747.98 | Q11: =R11/F11 -> 1808069.1 | R11: =P11*1.1 -> 725722.77 | S11: =R11*$S$3 -> 14514.455 | T11: =R11-N11-S11 -> 64655.302 | U11: =SUM(Q11:Q12)/2 -> 1152765.6
A12: =A11+1 -> 9 | B12: ĐỐ CHIA VÁCH | D12: 55 | E12: 1,4mm | F12: ='VÁCH KÍNH 55'!R18/1000 -> 1 | G12: ='VÁCH KÍNH 55'!V27 -> 260193.6 | H12: =G12/F12 -> 260193.6 | I12: =$I$3*F12 -> 108000 | J12: =$J$3*F12 -> 44000 | K12: =$K$3*F12 -> 24000 | L12: =$L$3*F12 -> 7000 | M12: =SUM(I12:L12) -> 183000 | N12: =SUM(I12:L12)+G12 -> 443193.6 | O12: =P12/F12 -> 452238.37 | P12: =N12/(1-$S$3) -> 452238.37 | Q12: =R12/F12 -> 497462.2 | R12: =P12*1.1 -> 497462.2 | S12: =R12*$S$3 -> 9949.2441 | T12: =R12-N12-S12 -> 44319.36
A14: 1 | B14: CỬA ĐI 1 CÁNH MỞ QUAY | D14: 83 | E14: 2,0mm | F14: ='ĐI QUAY 1 CÁNH 83'!F6/1000 -> 1.8 | G14: ='ĐI QUAY 1 CÁNH 83'!V19 -> 3669369 | H14: =G14/F14 -> 2038538.3 | I14: =$I$3*F14 -> 194400 | J14: =$J$3*F14 -> 79200 | K14: =$K$3*F14 -> 43200 | L14: =$L$3*F14 -> 12600 | M14: =SUM(I14:L14) -> 329400 | N14: =SUM(I14:L14)+G14 -> 3998769 | O14: =P14/F14 -> 2266875.8 | P14: =N14/(1-$S$3) -> 4080376.5 | Q14: =R14/F14 -> 2493563.4 | R14: =P14*1.1 -> 4488414.1 | S14: =R14*$S$3 -> 89768.283 | T14: =R14-N14-S14 -> 399876.9 | U14: =SUM(Q14:Q16)/3 -> 2282227.2
A15: =A14+1 -> 2 | B15: CỬA ĐI 2 CÁNH MỞ QUAY | D15: 83 | E15: 2,0mm | F15: ='ĐI QUAY 2 CÁNH 83 '!F6/1000 -> 3.6 | G15: ='ĐI QUAY 2 CÁNH 83 '!V21 -> 6491963.7 | H15: =G15/F15 -> 1803323.3 | I15: =$I$3*F15 -> 388800 | J15: =$J$3*F15 -> 158400 | K15: =$K$3*F15 -> 86400 | L15: =$L$3*F15 -> 25200 | M15: =SUM(I15:L15) -> 658800 | N15: =SUM(I15:L15)+G15 -> 7150763.7 | O15: =P15/F15 -> 2026860.5 | P15: =N15/(1-$S$3) -> 7296697.7 | Q15: =R15/F15 -> 2229546.5 | R15: =P15*1.1 -> 8026367.4 | S15: =R15*$S$3 -> 160527.35 | T15: =R15-N15-S15 -> 715076.37
A16: =A15+1 -> 3 | B16: CỬA ĐI 4 CÁNH MỞ QUAY | D16: 83 | E16: 2,0mm | F16: ='ĐI QUAY 4 CÁNH 83'!F6/1000 -> 7.2 | G16: ='ĐI QUAY 4 CÁNH 83'!V21 -> 12304147 | H16: =G16/F16 -> 1708909.3 | I16: =$I$3*F16 -> 777600 | J16: =$J$3*F16 -> 316800 | K16: =$K$3*F16 -> 172800 | L16: =$L$3*F16 -> 50400 | M16: =SUM(I16:L16) -> 1317600 | N16: =SUM(I16:L16)+G16 -> 13621747 | O16: =P16/F16 -> 1930519.7 | P16: =N16/(1-$S$3) -> 13899742 | Q16: =R16/F16 -> 2123571.6 | R16: =P16*1.1 -> 15289716 | S16: =R16*$S$3 -> 305794.32 | T16: =R16-N16-S16 -> 1362174.7
A17: =A16+1 -> 4 | B17: CỬA SỔ 1 CÁNH MỞ QUAY | D17: 83 | E17: 1,4mm | F17: ='SỔ QUAY 1 CÁNH 83'!F6/1000 -> 0.8 | G17: ='SỔ QUAY 1 CÁNH 83'!V17 -> 1856166.4 | H17: =G17/F17 -> 2320208 | I17: =$I$3*F17 -> 86400 | J17: =$J$3*F17 -> 35200 | K17: =$K$3*F17 -> 19200 | L17: =$L$3*F17 -> 5600 | M17: =SUM(I17:L17) -> 146400 | N17: =SUM(I17:L17)+G17 -> 2002566.4 | O17: =P17/F17 -> 2554293.9 | P17: =N17/(1-$S$3) -> 2043435.1 | Q17: =R17/F17 -> 2809723.3 | R17: =P17*1.1 -> 2247778.6 | S17: =R17*$S$3 -> 44955.573 | T17: =R17-N17-S17 -> 200256.64 | U17: =SUM(Q17:Q20)/4 -> 2533288.3
A18: =A17+1 -> 5 | B18: CỬA SỔ 2 CÁNH MỞ QUAY | D18: 83 | E18: 1,4mm | F18: ='SỔ QUAY 2 CÁNH 83 '!F6/1000 -> 1.8 | G18: ='SỔ QUAY 2 CÁNH 83 '!V19 -> 3550307.7 | H18: =G18/F18 -> 1972393.2 | I18: =$I$3*F18 -> 194400 | J18: =$J$3*F18 -> 79200 | K18: =$K$3*F18 -> 43200 | L18: =$L$3*F18 -> 12600 | M18: =SUM(I18:L18) -> 329400 | N18: =SUM(I18:L18)+G18 -> 3879707.7 | O18: =P18/F18 -> 2199380.8 | P18: =N18/(1-$S$3) -> 3958885.4 | Q18: =R18/F18 -> 2419318.9 | R18: =P18*1.1 -> 4354773.9 | S18: =R18*$S$3 -> 87095.479 | T18: =R18-N18-S18 -> 387970.77
A19: =A18+1 -> 6 | B19: CỬA SỔ 3 CÁNH MỞ QUAY | D19: 83 | E19: 1,4mm | F19: ='SỔ QUAY 3 CÁNH 83'!F6/1000 -> 2.4 | G19: ='SỔ QUAY 3 CÁNH 83'!V18 -> 5008171.1 | H19: =G19/F19 -> 2086738 | I19: =$I$3*F19 -> 259200 | J19: =$J$3*F19 -> 105600 | K19: =$K$3*F19 -> 57600 | L19: =$L$3*F19 -> 16800 | M19: =SUM(I19:L19) -> 439200 | N19: =SUM(I19:L19)+G19 -> 5447371.1 | O19: =P19/F19 -> 2316059.2 | P19: =N19/(1-$S$3) -> 5558542 | Q19: =R19/F19 -> 2547665.1 | R19: =P19*1.1 -> 6114396.2 | S19: =R19*$S$3 -> 122287.92 | T19: =R19-N19-S19 -> 544737.11
A20: =A19+1 -> 7 | B20: CỬA SỔ 4 CÁNH MỞ QUAY | D20: 83 | E20: 1,4mm | F20: ='SỔ QUAY 4 CÁNH 83'!F6/1000 -> 3.6 | G20: ='SỔ QUAY 4 CÁNH 83'!V20 -> 6898965.2 | H20: =G20/F20 -> 1916379.2 | I20: =$I$3*F20 -> 388800 | J20: =$J$3*F20 -> 158400 | K20: =$K$3*F20 -> 86400 | L20: =$L$3*F20 -> 25200 | M20: =SUM(I20:L20) -> 658800 | N20: =SUM(I20:L20)+G20 -> 7557765.2 | O20: =P20/F20 -> 2142223.7 | P20: =N20/(1-$S$3) -> 7712005.3 | Q20: =R20/F20 -> 2356446.1 | R20: =P20*1.1 -> 8483205.8 | S20: =R20*$S$3 -> 169664.12 | T20: =R20-N20-S20 -> 755776.52
A21: =A18+1 -> 6 | B21: VÁCH KÍNH | D21: 83 | E21: 1,4mm | F21: ='VÁCH KÍNH 83'!F6/1000 -> 1 | G21: ='VÁCH KÍNH 83'!V16 -> 1251600.1 | H21: =G21/F21 -> 1251600.1 | I21: =$I$3*F21 -> 108000 | J21: =$J$3*F21 -> 44000 | K21: =$K$3*F21 -> 24000 | L21: =$L$3*F21 -> 7000 | M21: =SUM(I21:L21) -> 183000 | N21: =SUM(I21:L21)+G21 -> 1434600.1 | O21: =P21/F21 -> 1463877.7 | P21: =N21/(1-$S$3) -> 1463877.7 | Q21: =R21/F21 -> 1610265.4 | R21: =P21*1.1 -> 1610265.4 | S21: =R21*$S$3 -> 32205.308 | T21: =R21-N21-S21 -> 143460.01 | U21: =SUM(Q21:Q22)/2 -> 1063723.7
A22: =A21+1 -> 7 | B22: ĐỐ CHIA VÁCH | D22: 83 | E22: 1,4mm | F22: ='VÁCH KÍNH 83'!R19/1000 -> 1 | G22: ='VÁCH KÍNH 83'!V28 -> 277762.2 | H22: =G22/F22 -> 277762.2 | I22: =$I$3*F22 -> 108000 | J22: =$J$3*F22 -> 44000 | K22: =$K$3*F22 -> 24000 | L22: =$L$3*F22 -> 7000 | M22: =SUM(I22:L22) -> 183000 | N22: =SUM(I22:L22)+G22 -> 460762.2 | O22: =P22/F22 -> 470165.51 | P22: =N22/(1-$S$3) -> 470165.51 | Q22: =R22/F22 -> 517182.06 | R22: =P22*1.1 -> 517182.06 | S22: =R22*$S$3 -> 10343.641 | T22: =R22-N22-S22 -> 46076.22
A23: =A20+1 -> 8 | B23: CỬA ĐI LÙA 2 CÁNH | D23: 83 | E23: 2,0mm | F23: ='ĐI LÙA 83 2 CÁNH'!F6/1000 -> 3.6 | G23: ='ĐI LÙA 83 2 CÁNH'!V22 -> 6290590.1 | H23: =G23/F23 -> 1747386.1 | I23: =$I$3*F23 -> 388800 | J23: =$J$3*F23 -> 158400 | K23: =$K$3*F23 -> 86400 | L23: =$L$3*F23 -> 25200 | M23: =SUM(I23:L23) -> 658800 | N23: =SUM(I23:L23)+G23 -> 6949390.1 | O23: =P23/F23 -> 1969781.8 | P23: =N23/(1-$S$3) -> 7091214.4 | Q23: =R23/F23 -> 2166760 | R23: =P23*1.1 -> 7800335.9 | S23: =R23*$S$3 -> 156006.72 | T23: =R23-N23-S23 -> 694939.01 | U23: =SUM(Q23:Q25)/3 -> 2112720
A24: =A23+1 -> 9 | B24: CỬA ĐI LÙA 3 CÁNH | D24: 83 | E24: 2,0mm | F24: ='ĐI Lùa 83 3 CÁNH'!F6/1000 -> 5.4 | G24: ='ĐI Lùa 83 3 CÁNH'!V22 -> 10000001 | H24: =G24/F24 -> 1851852 | I24: =$I$3*F24 -> 583200 | J24: =$J$3*F24 -> 237600 | K24: =$K$3*F24 -> 129600 | L24: =$L$3*F24 -> 37800 | M24: =SUM(I24:L24) -> 988200 | N24: =SUM(I24:L24)+G24 -> 10988201 | O24: =P24/F24 -> 2076379.6 | P24: =N24/(1-$S$3) -> 11212450 | Q24: =R24/F24 -> 2284017.6 | R24: =P24*1.1 -> 12333695 | S24: =R24*$S$3 -> 246673.9 | T24: =R24-N24-S24 -> 1098820.1
A25: =A24+1 -> 10 | B25: CỬA ĐI LÙA 4 CÁNH | D25: 83 | E25: 2,0mm | F25: ='ĐI Lùa 83 4 CÁNH'!F6/1000 -> 11.424 | G25: ='ĐI Lùa 83 4 CÁNH'!V23 -> 17118706 | H25: =G25/F25 -> 1498486.2 | I25: =$I$3*F25 -> 1233792 | J25: =$J$3*F25 -> 502656 | K25: =$K$3*F25 -> 274176 | L25: =$L$3*F25 -> 79968 | M25: =SUM(I25:L25) -> 2090592 | N25: =SUM(I25:L25)+G25 -> 19209298 | O25: =P25/F25 -> 1715802.2 | P25: =N25/(1-$S$3) -> 19601324 | Q25: =R25/F25 -> 1887382.4 | R25: =P25*1.1 -> 21561457 | S25: =R25*$S$3 -> 431229.13 | T25: =R25-N25-S25 -> 1920929.8
A26: =A25+1 -> 11 | B26: CỬA SỔ LÙA 2 CÁNH | D26: 83 | E26: 1,4mm | F26: ='Sổ lùA 2 CÁNH 83'!F6/1000 -> 1.8 | G26: ='Sổ lùA 2 CÁNH 83'!V17 -> 3508979.9 | H26: =G26/F26 -> 1949433.3 | I26: =$I$3*F26 -> 194400 | J26: =$J$3*F26 -> 79200 | K26: =$K$3*F26 -> 43200 | L26: =$L$3*F26 -> 12600 | M26: =SUM(I26:L26) -> 329400 | N26: =SUM(I26:L26)+G26 -> 3838379.9 | O26: =P26/F26 -> 2175952.3 | P26: =N26/(1-$S$3) -> 3916714.2 | Q26: =R26/F26 -> 2393547.6 | R26: =P26*1.1 -> 4308385.6 | S26: =R26*$S$3 -> 86167.713 | T26: =R26-N26-S26 -> 383837.99 | U26: =SUM(Q26:Q27)/2 -> 2384183.9
A27: =A26+1 -> 12 | B27: CỬA SỔ LÙA 4 CÁNH | D27: 83 | E27: 1,4mm | F27: ='Sổ lùa 4 CÁNH 83'!F6/1000 -> 4.48 | G27: ='Sổ lùa 4 CÁNH 83'!V18 -> 8658715.4 | H27: =G27/F27 -> 1932749 | I27: =$I$3*F27 -> 483840 | J27: =$J$3*F27 -> 197120 | K27: =$K$3*F27 -> 107520 | L27: =$L$3*F27 -> 31360 | M27: =SUM(I27:L27) -> 819840 | N27: =SUM(I27:L27)+G27 -> 9478555.4 | O27: =P27/F27 -> 2158927.5 | P27: =N27/(1-$S$3) -> 9671995.3 | Q27: =R27/F27 -> 2374820.3 | R27: =P27*1.1 -> 10639195 | S27: =R27*$S$3 -> 212783.9 | T27: =R27-N27-S27 -> 947855.54

Sheet ĐI QUAY 1 CÁNH
B1: BẢN SẢN XUẤT | N1: CHÍ PHÍ
B2: CỬA ĐI 1 CÁNH MỞ QUAY | H2: STT | I2: KÍCH THƯỚC SẢN XUẤT | N2: STT | O2: SẢN PHẨM | R2: MÉT DÀI ( mm ) | S2: TRỌNG LƯỢNG MD | T2: SỐ LƯỢNG TRỌNG LƯỢNG | U2: ĐƠN GIÁ | V2: THÀNH TIỀN | W2: GHI CHÚ
E3: W | F3: H | G3: Số lượng | I3: Tên | J3: Mã | K3: Kích thước | L3: Số lượng | N3: 1 | O3: KHUNG BAO CỬA ĐI | R3: =K4*L4+K5*L5 -> 5372 | S3: 1.236 | T3: =S3*R3 -> 6639.792 | U3: 198000 | V3: =U3*T3/1000 -> 1314678.8
E4: 940 | F4: 2216 | G4: 1 | H4: 01 | I4: Ngang K.B | K4: =E4 -> 940 | L4: =G4*1 -> 1 | N4: =N3+1 -> 2 | O4: CÁNH CỬA ĐI | R4: =K6*L6+K7*L7 -> 6046 | S4: 1.492 | T4: =S4*R4 -> 9020.632 | U4: 198000 | V4: =U4*T4/1000 -> 1786085.1
E5: KHẤU HAO | F5: DIỆN TÍCH | G5: SỐ KG | H5: 02 | I5: ĐỨNG K.B | K5: =F4 -> 2216 | L5: =G4*2 -> 2 | N5: =N4+1 -> 3 | O5: NẸP KÍNH CÁNH | R5: =R4 -> 6046 | S5: 0.276 | T5: =S5*R5 -> 1668.696 | U5: 198000 | V5: =U5*T5/1000 -> 330401.81
E6: =G6+T7 -> 18570.485 | F6: =F4*E4/1000 -> 2083.04 | G6: =SUM(T3:T6) -> 17686.176 | H6: 03 | I6: N. Cánh | K6: =K4-72-10 -> 858 | L6: =G4*2 -> 2 | N6: =N5+1 -> 4 | O6: ỐP CHÂN CÁNH | R6: =K8*L8 -> 797 | S6: 0.448 | T6: =S6*R6 -> 357.056 | U6: 198000 | V6: =U6*T6/1000 -> 70697.088
F7: HỞ NỀN | G7: ÂM NỀN | H7: 04 | I7: Đ. Cánh | K7: =IF(AND(F9="X",G9=""),K5-F8,0)+IF(AND(G9="X",F9=""),K5-G8,0) -> 2165 | L7: =G4*2 -> 2 | N7: =N6+1 -> 5 | O7: KHẤU HAO DX NHÔM | T7: =SUM(T3:T6)*U7 -> 884.3088 | U7: 0.05 | V7: =SUM(V3:V6)*U7 -> 175093.14
F8: 51 | G8: 31 | H8: 05 | I8: Ốp dưới | K8: =K6-61 -> 797 | L8: =G4*1 -> 1 | N8: =N7+1 -> 6 | O8: KE KHUNG BAO - 31*41 | T8: 2 | U8: 7700 | V8: =U8*T8 -> 15400
F9: X | H9: 06 | I9: Kính | J9: Ngang | K9: Cao | L9: Số lượng | N9: =N8+1 -> 7 | O9: KE CÁNH - 31*41 | T9: 4 | U9: 7700 | V9: =U9*T9 -> 30800 | W9: 4 KE VĨNH CỬU 1 CÁNH
H10: 07 | J10: =IF(K6-140>0,K6-140,"0") -> 718 | K10: =IF(K7-140>0,K7-140,"0") -> 2025 | L10: 1 | N10: =N9+1 -> 8 | O10: KE TĂNG CỨNG | T10: =T9*2+T8 -> 10 | U10: 100 | V10: =U10*T10 -> 1000 | W10: 8 KE TĂNG CỨNG 1 CÁNH
N11: =N10+1 -> 9 | O11: TỔNG CHI PHÍ VẬT LIỆU CHÍNH | V11: =SUM(V3:V10) -> 3724156
N12: STT | O12: SẢN PHẨM | R12: MÉT DÀI | S12: SỐ LƯỢNG | U12: ĐƠN GIÁ | V12: THÀNH TIỀN
N13: 1 | O13: RON KHUNG BAO | R13: =R3+R4 -> 11418 | S13: 1 | U13: 1000 | V13: =U13*R13*S13/1000 -> 11418
N14: =N13+1 -> 2 | O14: RON KÍNH | R14: =R4*2 -> 12092 | S14: 1 | U14: 1000 | V14: =U14*R14*S14/1000 -> 12092
N15: =N14+1 -> 3 | O15: NHỰA ỐP CHÂN | S15: 1 | U15: 2500 | V15: =U15*S15 -> 2500 | W15: 1 CẶP CHO 1 CÁNH
N16: =N15+1 -> 4 | O16: ỐC VÍT LIÊN KẾT | S16: 1 | U16: 1000 | V16: =U16*S16 -> 1000 | W16: 1 BỘ
N17: =N16+1 -> 5 | O17: GIẤY ĐÓNG GÓI + PE | S17: 1 | U17: 2000 | V17: =U17*S17 -> 2000 | W17: 1 BỘ
N18: =N17+1 -> 6 | O18: TỔNG CHI PHÍ VẬT TƯ CỬA | V18: =SUM(V13:V17) -> 29010
V19: =V11+V18 -> 3753166
H20: =F20 -> 0
K21: =J10*K10*L10/1000000 -> 1.45395
I22: =F6+'VÁCH KÍNH 55'!F6 -> 2484.42 | K22: =K21*220000 -> 319869
I23: =I22*200 -> 496884 | K23: =V19+K22 -> 4073035 | L23: =1.8*300000 -> 540000
K24: =K23/F6 -> 1955.3321 | L24: =K23+L23 -> 4613035
K25: =I23 -> 496884 | L25: =L24/F6 -> 2214.5686
K26: =K25+K23+K22 -> 4889788

Sheet ĐI QUAY 2 CÁNH
B1: BẢN SẢN XUẤT | N1: CHÍ PHÍ
B2: CỬA ĐI 1 CÁNH MỞ QUAY | H2: STT | I2: KÍCH THƯỚC SẢN XUẤT | N2: STT | O2: SẢN PHẨM | R2: MÉT DÀI | S2: TRỌNG LƯỢNG MD | T2: SỐ LƯỢNG TRỌNG LƯỢNG T | U2: ĐƠN GIÁ | V2: THÀNH TIỀN | W2: GHI CHÚ
E3: W | F3: H | G3: Số lượng | I3: Tên | J3: Mã | K3: Kích thước | L3: Số lượng | N3: 1 | O3: KHUNG BAO CỬA ĐI | R3: =K4*L4+K5*L5 -> 6300 | S3: 1.236 | T3: =S3*R3 -> 7786.8 | U3: 198000 | V3: =U3*T3/1000 -> 1541786.4
E4: 1500 | F4: 2400 | G4: 1 | H4: 1 | I4: Ngang K.B | J4: =CONCATENATE($G$2,"-",$D$11,"-","3328","-","1") -> --3328-1 | K4: =E4 -> 1500 | L4: =G4*1 -> 1 | N4: =N3+1 -> 2 | O4: CÁNH CỬA ĐI | R4: =K6*L6+K7*L7 -> 12220 | S4: 1.492 | T4: =S4*R4 -> 18232.24 | U4: 198000 | V4: =U4*T4/1000 -> 3609983.5
E5: KHẤU HAO | F5: DIỆN TÍCH | G5: SỐ KG | H5: =H4+1 -> 2 | I5: Đứng K.B | J5: =CONCATENATE($G$2,"-",$D$11,"-","3328","-","2") -> --3328-2 | K5: =F4 -> 2400 | L5: =G4*2 -> 2 | N5: =N4+1 -> 3 | O5: NẸP KÍNH CÁNH | R5: =R4 -> 12220 | S5: 0.276 | T5: =S5*R5 -> 3372.72 | U5: 198000 | V5: =U5*T5/1000 -> 667798.56
E6: =G6+T8 -> 34497.254 | F6: =F4*E4/1000 -> 3600 | G6: =SUM(T3:T7) -> 32240.424 | H6: =H5+1 -> 3 | I6: N/Cánh | J6: =CONCATENATE($G$2,"-",$D$11,"-","3332","-","1") -> --3332-1 | K6: =IF(ROUNDDOWN((E4-36*2-15),0)/2<0,"0",ROUNDDOWN((E4-72-15)/2,0)) -> 706 | L6: =G4*4 -> 4 | N6: =N5+1 -> 4 | O6: ỐP CHÂN CÁNH | R6: =K9*L9 -> 1290 | S6: 0.448 | T6: =S6*R6 -> 577.92 | U6: 198000 | V6: =U6*T6/1000 -> 114428.16
F7: HỞ NỀN | G7: ÂM NỀN | H7: =H6+1 -> 4 | I7: Đ/Cánh | J7: =CONCATENATE($G$2,"-",$D$11,"-","3332","-","2") -> --3332-2 | K7: =IF(AND(F9="X",G9=""),K5-F8,0)+IF(AND(G9="X",F9=""),K5-G8,0) -> 2349 | L7: =G4*4 -> 4 | N7: =N6+1 -> 5 | O7: ĐỐ ĐỘNG | R7: =K8*L8 -> 2296 | S7: 0.989 | T7: =S7*R7 -> 2270.744 | U7: 198000 | V7: =U7*T7/1000 -> 449607.31
F8: 51 | G8: 31 | H8: =H7+1 -> 5 | I8: Đố động | J8: =CONCATENATE($G$2,"-",$D$11,"-","3323A","-","1") -> --3323A-1 | K8: =IF(G9="x",ROUNDDOWN(K7-30-4,0),ROUNDDOWN(K7-34-19,0)) -> 2296 | L8: =G4 -> 1 | N8: =N7+1 -> 6 | O8: KHẤU HAO DX NHÔM | T8: =SUM(T3:T7)*U8 -> 2256.8297 | U8: 0.07 | V8: =SUM(V3:V7)*U8 -> 446852.28
F9: X | H9: =H8+1 -> 6 | I9: Nẹp dưới | J9: =CONCATENATE($G$2,"-",$D$11,"-","3329A","-","1") -> --3329A-1 | K9: =K6-61 -> 645 | L9: =G4*2 -> 2 | N9: =N8+1 -> 7 | O9: KE VĨNH CỬU KHUNG BAO | T9: 2 | U9: 7700 | V9: =U9*T9 -> 15400
H10: =H9+1 -> 7 | I10: Kính | J10: Ngang | K10: Cao | L10: Số lượng | N10: =N9+1 -> 8 | O10: KE VĨNH CỬU CÁNH | T10: 8 | U10: 7700 | V10: =U10*T10 -> 61600 | W10: 4 KE VĨNH CỬU 1 CÁNH
H11: =H10+1 -> 8 | J11: =IF(K6-140>0,K6-140,"0") -> 566 | K11: =IF(K7-140>0,K7-140,"0") -> 2209 | L11: =G4*2 -> 2 | N11: =N10+1 -> 9 | O11: KE TĂNG CỨNG | T11: =T10*2+T9 -> 18 | U11: 100 | V11: =U11*T11 -> 1800 | W11: 8 KE TĂNG CỨNG 1 CÁNH
N12: =N11+1 -> 10 | O12: TỔNG CHI PHÍ VẬT LIỆU CHÍNH | V12: =SUM(V3:V11) -> 6909256.2
N13: STT | O13: SẢN PHẨM | R13: MÉT DÀI | S13: SỐ LƯỢNG | U13: ĐƠN GIÁ | V13: THÀNH TIỀN
N14: 1 | O14: RON KHUNG BAO | R14: =R3+R4+R7 -> 20816 | S14: 1 | U14: 1000 | V14: =U14*R14*S14/1000 -> 20816
N15: =N14+1 -> 2 | O15: RON KÍNH | R15: =R4*2 -> 24440 | S15: 1 | U15: 1000 | V15: =U15*R15*S15/1000 -> 24440
N16: =N15+1 -> 3 | O16: NHỰA ỐP CHÂN | S16: 2 | U16: 2500 | V16: =U16*S16 -> 5000 | W16: 1 CẶP CHO 1 CÁNH
N17: =N16+1 -> 4 | O17: NHỰA ĐỐ ĐỘNG | S17: 1 | U17: 2500 | V17: =U17*S17 -> 2500 | W17: 1 CÁI CHO 1 ĐẦU TRÊN
N18: =N17+1 -> 5 | O18: ỐC VÍT LIÊN KẾT | S18: 1 | U18: 1000 | V18: =U18*S18 -> 1000
N19: =N18+1 -> 6 | O19: GIẤY ĐÓNG GÓI + PE | S19: 1 | U19: 2000 | V19: =U19*S19 -> 2000 | W19: 1 BỘ CỬA
N20: =N19+1 -> 7 | O20: TỔNG CHI PHÍ VẬT TƯ CỬA | V20: =SUM(V14:V19) -> 55756
V21: =V12+V20 -> 6965012.2
V22: =J11*K11*L11*0.28 -> 700164.64
V23: =F6*450 -> 1620000
V24: =V21+V22+V23 -> 9285176.9
V25: =F6*3300*G4 -> 11880000
V26: =V24/V25 -> 0.78158054

Sheet ĐI QUAY 4 CÁNH
B1: BẢN SẢN XUẤT | N1: CHÍ PHÍ
H2: STT | I2: KÍCH THƯỚC SẢN XUẤT | N2: STT | O2: SẢN PHẨM | R2: MÉT DÀI | S2: TRỌNG LƯỢNG MD | T2: SỐ LƯỢNG TRỌNG LƯỢNG T | U2: ĐƠN GIÁ | V2: THÀNH TIỀN | W2: GHI CHÚ
E3: W | F3: H | G3: Số lượng | I3: Tên | J3: Mã | K3: Kích thước | L3: Số lượng | N3: 1 | O3: KHUNG BAO CỬA ĐI | R3: =K4*L4+K5*L5 -> 7670 | S3: 1.236 | T3: =S3*R3 -> 9480.12 | U3: 195000 | V3: =U3*T3/1000 -> 1848623.4
E4: 2970 | F4: 2350 | G4: 1 | H4: 1 | I4: Ngang K.B | J4: =CONCATENATE($G$2,"-",$D$11,"-","3328","-","1") -> --3328-1 | K4: =E4 -> 2970 | L4: =G4*1 -> 1 | N4: =N3+1 -> 2 | O4: CÁNH CỬA ĐI | R4: =K6*L6+K7*L7 -> 24136 | S4: 1.492 | T4: =S4*R4 -> 36010.912 | U4: 195000 | V4: =U4*T4/1000 -> 7022127.8
E5: KHẤU HAO | F5: DIỆN TÍCH | G5: SỐ KG | H5: =H4+1 -> 2 | I5: Đứng K.B | J5: =CONCATENATE($G$2,"-",$D$11,"-","3328","-","2") -> --3328-2 | K5: =F4 -> 2350 | L5: =G4*2 -> 2 | N5: =N4+1 -> 3 | O5: NẸP KÍNH CÁNH | R5: =R4 -> 24136 | S5: 0.276 | T5: =S5*R5 -> 6661.536 | U5: 195000 | V5: =U5*T5/1000 -> 1298999.5
E6: =G6+T8 -> 66163.529 | F6: =F4*E4/1000 -> 6979.5 | G6: =SUM(T3:T7) -> 61835.074 | H6: =H5+1 -> 3 | I6: N/Cánh | J6: =CONCATENATE($G$2,"-",$D$11,"-","3332","-","1") -> --3332-1 | K6: =IF((E4-36*2-25)/4<0,"0",ROUNDDOWN((E4-72-25)/4,0)) -> 718 | L6: =G4*8 -> 8 | N6: =N5+1 -> 4 | O6: ỐP CHÂN CÁNH | R6: =K8*L8 -> 6738 | S6: 0.448 | T6: =S6*R6 -> 3018.624 | U6: 195000 | V6: =U6*T6/1000 -> 588631.68
F7: HỞ NỀN | G7: ÂM NỀN | H7: =H6+1 -> 4 | I7: Đ/Cánh | J7: =CONCATENATE($G$2,"-",$D$11,"-","3332","-","2") -> --3332-2 | K7: =IF(AND(F9="X",G9=""),K5-F8,0)+IF(AND(G9="X",F9=""),K5-G8,0) -> 2299 | L7: =G4*8 -> 8 | N7: =N6+1 -> 5 | O7: ĐỐ ĐỘNG | R7: =K8*L8 -> 6738 | S7: 0.989 | T7: =S7*R7 -> 6663.882 | U7: 195000 | V7: =U7*T7/1000 -> 1299457
F8: 51 | G8: 31 | H8: =H7+1 -> 5 | I8: Đố động | J8: =CONCATENATE($G$2,"-",$D$11,"-","3323A","-","1") -> --3323A-1 | K8: =IF(G7="x",ROUNDDOWN(K7-30-4,0),ROUNDDOWN(K7-34-19,0)) -> 2246 | L8: =G4*3 -> 3 | N8: =N7+1 -> 6 | O8: KHẤU HAO DX NHÔM | T8: =SUM(T3:T7)*U8 -> 4328.4552 | U8: 0.07 | V8: =SUM(V3:V7)*U8 -> 844048.76
F9: X | H9: =H8+1 -> 6 | I9: Nẹp dưới | J9: =CONCATENATE($G$2,"-",$D$11,"-","3329A","-","1") -> --3329A-1 | K9: =K6-61 -> 657 | L9: =G4*4 -> 4 | N9: =N8+1 -> 7 | O9: KE VĨNH CỬU KHUNG BAO | T9: 2 | U9: 7700 | V9: =U9*T9 -> 15400
H10: =H9+1 -> 7 | I10: Kính | J10: Ngang | K10: Cao | L10: Số lượng | N10: =N9+1 -> 8 | O10: KE VĨNH CỬU CÁNH | T10: 16 | U10: 7700 | V10: =U10*T10 -> 123200 | W10: 4 KE VĨNH CỬU 1 CÁNH
H11: =H10+1 -> 8 | J11: =IF(K6-145>0,K6-145,"0") -> 573 | K11: =IF(K7-140>0,K7-140,"0") -> 2159 | L11: =G4*4 -> 4 | N11: =N10+1 -> 9 | O11: KE TĂNG CỨNG | T11: =T10*2+T9 -> 34 | U11: 100 | V11: =U11*T11 -> 3400 | W11: 8 KE TĂNG CỨNG 1 CÁNH
N12: =N11+1 -> 10 | O12: TỔNG CHI PHÍ VẬT LIỆU CHÍNH | V12: =SUM(V3:V11) -> 13043888
J13: =V12 -> 13043888 | N13: STT | O13: SẢN PHẨM | R13: MÉT DÀI | S13: SỐ LƯỢNG | U13: ĐƠN GIÁ | V13: THÀNH TIỀN
J14: =F6*450 -> 3140775 | N14: 1 | O14: RON KHUNG BAO | R14: =R3+R4+R7 -> 38544 | S14: 1 | U14: 1000 | V14: =U14*R14*S14/1000 -> 38544
J15: =J11*K11*L11*0.215 -> 1063912 | N15: =N14+1 -> 2 | O15: RON KÍNH | R15: =R4*2 -> 48272 | S15: 1 | U15: 1000 | V15: =U15*R15*S15/1000 -> 48272 | W15: 1 CẶP CHO 1 CÁNH
N16: =N15+1 -> 3 | O16: NHỰA ỐP CHÂN | S16: 1 | U16: 2500 | V16: =U16*S16 -> 2500 | W16: 1 CÁI CHO 1 ĐẦU TRÊN
N17: =N16+1 -> 4 | O17: NHỰA ĐỐ ĐỘNG | S17: 3 | U17: 2500 | V17: =U17*S17 -> 7500
N18: =N17+1 -> 5 | O18: ỐC VÍT LIÊN KẾT | S18: 1 | U18: 1000 | V18: =U18*S18 -> 1000 | W18: 1 BỘ CỬA
N19: =N18+1 -> 6 | O19: GIẤY ĐÓNG GÓI + PE | S19: 1 | U19: 2000 | V19: =U19*S19 -> 2000 | W19: 1 BỘ CỬA
N20: =N19+1 -> 7 | O20: TỔNG CHI PHÍ VẬT TƯ CỬA | V20: =SUM(V14:V19) -> 99816
H21: =F21 -> 0 | V21: =V12+V20 -> 13143704

Sheet SỔ QUAY 1CÁNH
B1: BẢN SẢN XUẤT | N1: CHÍ PHÍ
B2: THÔNG TIN CÔNG TRÌNH | H2: STT | I2: KÍCH THƯỚC SẢN XUẤT | N2: STT | O2: SẢN PHẨM | R2: MÉT DÀI | S2: TRỌNG LƯỢNG MD | T2: SỐ LƯỢNG TRỌNG LƯỢNG T | U2: ĐƠN GIÁ | V2: THÀNH TIỀN | W2: GHI CHÚ
E3: W | F3: H | G3: Số lượng | I3: Tên | J3: Mã | K3: Kích thước | L3: Số lượng | N3: 1 | O3: KHUNG BAO CỬA SỔ | R3: =K4*L4+K5*L5 -> 4400 | S3: 0.853 | T3: =S3*R3 -> 3753.2 | U3: 195000 | V3: =U3*T3/1000 -> 731874
E4: 700 | F4: 1500 | G4: 1 | H4: 01 | I4: Ngang K.B | J4: =CONCATENATE($G$2,"-",$D$9,"-","3318","-","1") -> --3318-1 | K4: =E4 -> 700 | L4: =G4*2 -> 2 | N4: =N3+1 -> 2 | O4: CÁNH CỬA SỔ | R4: =K6*L6+K7*L7 -> 4200 | S4: 1.042 | T4: =S4*R4 -> 4376.4 | U4: 195000 | V4: =U4*T4/1000 -> 853398
E5: KHẤU HAO | F5: DIỆN TÍCH | G5: SỐ KG | H5: 02 | I5: Đứng K.B | J5: =CONCATENATE($G$2,"-",$D$9,"-","3318","-","2") -> --3318-2 | K5: =F4 -> 1500 | L5: =G4*2 -> 2 | N5: =N4+1 -> 3 | O5: NẸP KÍNH CÁNH | R5: =R4 -> 4200 | S5: 0.276 | T5: =S5*R5 -> 1159.2 | U5: 195000 | V5: =U5*T5/1000 -> 226044
E6: =G6+T6 -> 9939.016 | F6: =F4*E4/1000 -> 1050 | G6: =SUM(T3:T5) -> 9288.8 | H6: 03 | I6: N. Cánh | J6: =CONCATENATE($G$2,"-",$D$9,"-","8092","-","1") -> --8092-1 | K6: =IF(E4-40-10<0,"0",E4-40-10) -> 650 | L6: =G4*2 -> 2 | N6: =N5+1 -> 4 | O6: KHẤU HAO DX NHÔM | T6: =SUM(T3:T5)*U6 -> 650.216 | U6: 0.07 | V6: =SUM(V3:V5)*U6 -> 126792.12
H7: 04 | I7: Đ. Cánh | J7: =CONCATENATE($G$2,"-",$D$9,"-","8092","-","2") -> --8092-2 | K7: =IF(F4-40-10<0,"0",F4-40-10) -> 1450 | L7: =G4*2 -> 2 | N7: =N6+1 -> 5 | O7: KE KHUNG BAO - 14*43 | T7: 4 | U7: 4400 | V7: =U7*T7 -> 17600 | W7: 4 KE VĨNH CỬU 1 KHUNG
H8: 05 | I8: KÍNH | J8: Ngang | K8: Cao | L8: Số lượng | N8: =N7+1 -> 6 | O8: KE CÁNH - 25*40 | T8: 4 | U8: 5100 | V8: =U8*T8 -> 20400 | W8: 4 KE VĨNH CỬU 1 CÁNH
H9: 06 | J9: =IF(K6-120>0,K6-120,"0") -> 530 | K9: =IF(K7-120>0,K7-120,"0") -> 1330 | L9: =G4 -> 1 | N9: =N8+1 -> 7 | O9: KE TĂNG CỨNG | T9: =T8*2+T7 -> 12 | U9: 100 | V9: =U9*T9 -> 1200 | W9: 8 KE TĂNG CỨNG 1 CÁNH
N10: =N9+1 -> 8 | O10: TỔNG CHI PHÍ VẬT LIỆU CHÍNH | V10: =SUM(V3:V9) -> 1977308.1
L11: =J9*K9*L9/1000000 -> 0.7049 | N11: STT | O11: SẢN PHẨM | R11: MÉT DÀI | S11: SỐ LƯỢNG | U11: ĐƠN GIÁ | V11: THÀNH TIỀN
L12: =L11*1600 -> 1127.84 | N12: 1 | O12: RON KHUNG BAO | R12: =R3+R4 -> 8600 | S12: 1 | U12: 1000 | V12: =U12*R12*S12/1000 -> 8600
L13: =F6*450 -> 472500 | N13: =N12+1 -> 2 | O13: RON KÍNH | R13: =R4*2 -> 8400 | S13: 1 | U13: 1000 | V13: =U13*R13*S13/1000 -> 8400
L14: =F6*200 -> 210000 | N14: =N13+1 -> 3 | O14: ỐC VÍT LIÊN KẾT | S14: 1 | U14: 1000 | V14: =U14*S14 -> 1000 | W14: 1 BỘ
L15: =V17+L13+L12 -> 2470936 | N15: =N14+1 -> 4 | O15: GIẤY ĐÓNG GÓI + PE | S15: 1 | U15: 2000 | V15: =U15*S15 -> 2000 | W15: 1 BỘ
N16: =N15+1 -> 5 | O16: TỔNG CHI PHÍ VẬT TƯ CỬA | V16: =SUM(V12:V15) -> 20000
L17: =F6*4200 -> 4410000 | V17: =V10+V16 -> 1997308.1
L18: =L15/L17 -> 0.56030294

Sheet Sổ QUAY 2 CÁNH
B1: BẢN SẢN XUẤT | N1: CHÍ PHÍ
B2: THÔNG TIN CÔNG TRÌNH | I2: KÍCH THƯỚC SẢN XUẤT | N2: STT | O2: SẢN PHẨM | R2: MÉT DÀI | S2: TRỌNG LƯỢNG MD | T2: SỐ LƯỢNG TRỌNG LƯỢNG T | U2: ĐƠN GIÁ | V2: THÀNH TIỀN | W2: GHI CHÚ
E3: W | F3: H | G3: Số lượng | H3: STT | I3: Tên | J3: Mã | K3: Kích thước | L3: Số lượng | N3: 1 | O3: KHUNG BAO CỬA SỔ | R3: =K4*L4+K5*L5 -> 5600 | S3: 0.853 | T3: =S3*R3 -> 4776.8 | U3: 178000 | V3: =U3*T3/1000 -> 850270.4
E4: 1800 | F4: 1000 | G4: 1 | H4: 1 | I4: Ngang K.B | J4: =CONCATENATE($G$2,"-",$D$10,"-","3318","-","1") -> --3318-1 | K4: =E4 -> 1800 | L4: =G4*2 -> 2 | N4: =N3+1 -> 2 | O4: CÁNH CỬA SỔ | R4: =K6*L6+K7*L7 -> 7288 | S4: 1.042 | T4: =S4*R4 -> 7594.096 | U4: 178000 | V4: =U4*T4/1000 -> 1351749.1
E5: KHẤU HAO | F5: DIỆN TÍCH | G5: SỐ KG | H5: =H4+1 -> 2 | I5: Đứng K.B | J5: =CONCATENATE($G$2,"-",$D$10,"-","3318","-","2") -> --3318-2 | K5: =F4 -> 1000 | L5: =G4*2 -> 2 | N5: =N4+1 -> 3 | O5: NẸP KÍNH CÁNH | R5: =R4 -> 7288 | S5: 0.276 | T5: =S5*R5 -> 2011.488 | U5: 178000 | V5: =U5*T5/1000 -> 358044.86
E6: =G6+T7 -> 16022.608 | F6: =F4*E4/1000 -> 1800 | G6: =SUM(T3:T6) -> 15259.627 | H6: =H5+1 -> 3 | I6: N/Cánh | J6: =CONCATENATE($G$2,"-",$D$10,"-","3202","-","1") -> --3202-1 | K6: =IF(ROUNDDOWN((E4-40-16)/2,0)<0,"0",ROUNDDOWN((E4-40-16)/2,0)) -> 872 | L6: =G4*4 -> 4 | N6: =N5+1 -> 4 | O6: ĐỐ ĐỘNG | R6: =K8*L8 -> 887 | S6: 0.989 | T6: =S6*R6 -> 877.243 | U6: 178000 | V6: =U6*T6/1000 -> 156149.25
H7: =H6+1 -> 4 | I7: Đ/Cánh | J7: =CONCATENATE($G$2,"-",$D$10,"-","3202","-","2") -> --3202-2 | K7: =IF(F4-40-10<0,"0",ROUNDDOWN(F4-40-10,0)) -> 950 | L7: =G4*4 -> 4 | N7: =N6+1 -> 5 | O7: KHẤU HAO DX NHÔM | T7: =SUM(T3:T6)*U7 -> 762.98135 | U7: 0.05 | V7: =SUM(V3:V6)*U7 -> 135810.68
H8: =H7+1 -> 5 | I8: Đố động | J8: =CONCATENATE($G$2,"-",$D$10,"-","3323A","-","1") -> --3323A-1 | K8: =K7-63 -> 887 | L8: =G4*1 -> 1 | N8: =N7+1 -> 6 | O8: KE KHUNG BAO - 14*43 | T8: 4 | U8: 4400 | V8: =U8*T8 -> 17600
H9: =H8+1 -> 6 | I9: KÍNH | J9: Ngang | K9: Cao | L9: Số lượng | N9: =N8+1 -> 7 | O9: KE CÁNH - 25*40 | T9: 8 | U9: 5100 | V9: =U9*T9 -> 40800 | W9: 4 KE VĨNH CỬU 1 CÁNH
H10: =H9+1 -> 7 | J10: =IF(K6-120>0,K6-120,"0") -> 752 | K10: =IF(K7-120>0,K7-120,"0") -> 830 | L10: =G4*2 -> 2 | N10: =N9+1 -> 8 | O10: KE TĂNG CỨNG | T10: =T9*2+T8 -> 20 | U10: 100 | V10: =U10*T10 -> 2000 | W10: 8 KE TĂNG CỨNG 1 CÁNH
N11: =N10+1 -> 9 | O11: TỔNG CHI PHÍ VẬT LIỆU CHÍNH | V11: =SUM(V3:V10) -> 2912424.3
N12: STT | O12: SẢN PHẨM | R12: MÉT DÀI | S12: SỐ LƯỢNG | U12: ĐƠN GIÁ | V12: THÀNH TIỀN
N13: 1 | O13: RON KHUNG BAO | R13: =R3+R4+R6 -> 13775 | S13: 1 | U13: 1000 | V13: =U13*R13*S13/1000 -> 13775
N14: =N13+1 -> 2 | O14: RON KÍNH | R14: =R4*2 -> 14576 | S14: 1 | U14: 1000 | V14: =U14*R14*S14/1000 -> 14576
N15: =N14+1 -> 3 | O15: NHỰA ĐỐ ĐỘNG | S15: 1 | U15: 2500 | V15: =U15*S15 -> 2500 | W15: 1 CẶP
N16: =N15+1 -> 4 | O16: ỐC VÍT LIÊN KẾT | S16: 1 | U16: 1000 | V16: =U16*S16 -> 1000 | W16: 1 BỘ
N17: =N16+1 -> 5 | O17: GIẤY ĐÓNG GÓI + PE | S17: 1 | U17: 2000 | V17: =U17*S17 -> 2000 | W17: 1 BỘ
N18: =N17+1 -> 6 | O18: TỔNG CHI PHÍ VẬT TƯ CỬA | V18: =SUM(V13:V17) -> 33851
V19: =V11+V18 -> 2946275.3

Sheet Sổ QUAY 3 CÁNH -Đố tĩnh
B1: BẢN SẢN XUẤT | N1: CHÍ PHÍ
B2: THÔNG TIN CÔNG TRÌNH | I2: KÍCH THƯỚC SẢN XUẤT | N2: STT | O2: SẢN PHẨM | R2: MÉT DÀI | S2: TRỌNG LƯỢNG MD | T2: SỐ LƯỢNG TRỌNG LƯỢNG T | U2: ĐƠN GIÁ | V2: THÀNH TIỀN | W2: GHI CHÚ
E3: W | F3: H | G3: Số lượng | H3: STT | I3: Tên | J3: Mã | K3: Kích thước | L3: Số lượng | N3: 1 | O3: KHUNG BAO CỬA SỔ | R3: =K4*L4+K5*L5 -> 6800 | S3: 0.853 | T3: =S3*R3 -> 5800.4 | U3: 178000 | V3: =U3*T3/1000 -> 1032471.2
E4: 2400 | F4: 1000 | G4: 1 | H4: 01 | I4: Ngang K.B | J4: =CONCATENATE($G$2,"-",$D$10,"-","3318","-","1") -> --3318-1 | K4: =E4 -> 2400 | L4: =G4*2 -> 2 | N4: =N3+1 -> 2 | O4: CÁNH CỬA SỔ | R4: =K6*L6+K7*L7 -> 10296 | S4: 1.042 | T4: =S4*R4 -> 10728.432 | U4: 178000 | V4: =U4*T4/1000 -> 1909660.9
E5: KHẤU HAO | F5: DIỆN TÍCH | G5: SỐ KG | H5: 02 | I5: Đứng K.B | J5: =CONCATENATE($G$2,"-",$D$10,"-","3318","-","2") -> --3318-2 | K5: =F4 -> 1000 | L5: =G4*2 -> 2 | N5: =N4+1 -> 3 | O5: NẸP KÍNH CÁNH | R5: =R4 -> 10296 | S5: 0.276 | T5: =S5*R5 -> 2841.696 | U5: 178000 | V5: =U5*T5/1000 -> 505821.89
E6: =G6+T7 -> 22465.934 | F6: =F4*E4/1000 -> 2400 | G6: =SUM(T3:T6) -> 21396.128 | H6: 03 | I6: N/Cánh | J6: =CONCATENATE($G$2,"-",$D$10,"-","3202","-","1") -> --3202-1 | K6: =IF(ROUNDDOWN((E4-40-30-30)/3,0)<0,"0",ROUNDDOWN((E4-40-30-30)/3,0)) -> 766 | L6: =G4*6 -> 6 | N6: =N5+1 -> 4 | O6: ĐỐ TĨNH | R6: =K8*L8 -> 1920 | S6: 1.055 | T6: =S6*R6 -> 2025.6 | U6: 178000 | V6: =U6*T6/1000 -> 360556.8
H7: 04 | I7: Đ/Cánh | J7: =CONCATENATE($G$2,"-",$D$10,"-","3202","-","2") -> --3202-2 | K7: =IF(F4-40-10<0,"0",F4-40-10) -> 950 | L7: =G4*6 -> 6 | N7: =N6+1 -> 5 | O7: KHẤU HAO DX NHÔM | T7: =SUM(T3:T6)*U7 -> 1069.8064 | U7: 0.05 | V7: =SUM(V3:V6)*U7 -> 190425.54
H8: 05 | I8: Đố tĩnh | J8: =CONCATENATE($G$2,"-",$D$10,"-","3313","-","1") -> --3313-1 | K8: =IF(F4-40<0,"0",F4-40) -> 960 | L8: =G4*2 -> 2 | N8: =N7+1 -> 6 | O8: KE KHUNG BAO - 14*43 | T8: 4 | U8: 4400 | V8: =U8*T8 -> 17600
I9: KÍNH | J9: Ngang | K9: Cao | L9: Số lượng | N9: =N8+1 -> 7 | O9: KE CÁNH - 25*40 | T9: 12 | U9: 5100 | V9: =U9*T9 -> 61200 | W9: 4 KE VĨNH CỬU 1 CÁNH
J10: =IF(K6-125>0,K6-125,"0") -> 641 | K10: =IF(K7-125>0,K7-125,"0") -> 825 | L10: =G4*3 -> 3 | N10: =N9+1 -> 8 | O10: KE TĂNG CỨNG | T10: =T9*2+T8 -> 28 | U10: 100 | V10: =U10*T10 -> 2800 | W10: 8 KE TĂNG CỨNG 1 CÁNH
N11: =N10+1 -> 9 | O11: TỔNG CHI PHÍ VẬT LIỆU CHÍNH | V11: =SUM(V3:V10) -> 4080536.3
N12: STT | O12: SẢN PHẨM | R12: MÉT DÀI | S12: SỐ LƯỢNG | U12: ĐƠN GIÁ | V12: THÀNH TIỀN
N13: 1 | O13: RON KHUNG BAO | R13: =R3+R6+R4 -> 19016 | S13: 1 | U13: 1000 | V13: =U13*R13/1000 -> 19016
N14: =N13+1 -> 2 | O14: RON KÍNH | R14: =R4*2 -> 20592 | S14: 1 | U14: 1000 | V14: =U14*R14/1000 -> 20592
N15: 3 | O15: ỐC VÍT LIÊN KẾT | S15: 1 | U15: 1000 | V15: =U15*S15 -> 1000 | W15: 1 BỘ
N16: =N15+1 -> 4 | O16: GIẤY ĐÓNG GÓI + PE | S16: 1 | U16: 2000 | V16: =U16*S16 -> 2000 | W16: 1 BỘ
N17: =N16+1 -> 5 | O17: TỔNG CHI PHÍ VẬT TƯ CỬA | V17: =SUM(V13:V16) -> 42608
V18: =V11+V17 -> 4123144.3
W19: `

Sheet Sổ QUAY 4 CÁNH đố tĩnh
B1: BẢN SẢN XUẤT | N1: CHÍ PHÍ
I2: KÍCH THƯỚC SẢN XUẤT | N2: STT | O2: SẢN PHẨM | R2: MÉT DÀI | S2: TRỌNG LƯỢNG MD | T2: SỐ LƯỢNG TRỌNG LƯỢNG T | U2: ĐƠN GIÁ | V2: THÀNH TIỀN | W2: GHI CHÚ
E3: W | F3: H | G3: Số lượng | H3: STT | I3: Tên | J3: Mã | K3: Kích thước | L3: Số lượng | N3: 1 | O3: KHUNG BAO CỬA SỔ | R3: =K4*L4+K5*L5 -> 9200 | S3: 0.853 | T3: =S3*R3 -> 7847.6 | U3: 178000 | V3: =U3*T3/1000 -> 1396872.8
E4: 3600 | F4: 1000 | G4: 1 | H4: 01 | I4: Ngang K.B | J4: =CONCATENATE($G$2,"-",$D$11,"-","3318","-","1") -> --3318-1 | K4: =E4 -> 3600 | L4: =G4*2 -> 2 | N4: =N3+1 -> 2 | O4: CÁNH CỬA SỔ | R4: =K7*L7+K8*L8 -> 14584 | S4: 1.052 | T4: =S4*R4 -> 15342.368 | U4: 178000 | V4: =U4*T4/1000 -> 2730941.5
E5: KHẤU HAO | F5: DIỆN TÍCH | G5: SỐ KG | H5: 02 | I5: Đứng K.B | J5: =CONCATENATE($G$2,"-",$D$11,"-","3318","-","2") -> --3318-2 | K5: =F4 -> 1000 | L5: =G4*2 -> 2 | N5: =N4+1 -> 3 | O5: NẸP KÍNH CÁNH | R5: =R4 -> 14584 | S5: 0.276 | T5: =S5*R5 -> 4025.184 | U5: 178000 | V5: =U5*T5/1000 -> 716482.75
E6: =G6+T8 -> 31621.818 | F6: =F4*E4/1000 -> 3600 | G6: =SUM(T3:T7) -> 30116.017 | H6: 03 | I6: Đố tĩnh | J6: =CONCATENATE($G$2,"-",$D$11,"-","3313","-","1") -> --3313-1 | K6: =F4-40 -> 960 | L6: =G4*2 -> 2 | N6: =N5+1 -> 4 | O6: ĐỐ ĐỘNG | R6: =K9*L9 -> 885 | S6: 0.989 | T6: =S6*R6 -> 875.265 | U6: 178000 | V6: =U6*T6/1000 -> 155797.17
H7: 04 | I7: N/Cánh | J7: =CONCATENATE($G$2,"-",$D$11,"-","3202","-","1") -> --3202-1 | K7: =ROUNDDOWN(IF((E4-105)/4<0,"0",(E4-105)/4),0) -> 873 | L7: =G4*8 -> 8 | N7: =N6+1 -> 5 | O7: ĐỐ TĨNH | R7: =K6*L6 -> 1920 | S7: 1.055 | T7: =S7*R7 -> 2025.6 | U7: 178000 | V7: =U7*T7/1000 -> 360556.8
H8: 05 | I8: Đ/Cánh | J8: =CONCATENATE($G$2,"-",$D$11,"-","3202","-","2") -> --3202-2 | K8: =IF(F4-40-10<0,"0",F4-40-10) -> 950 | L8: =G4*8 -> 8 | N8: =N7+1 -> 6 | O8: KHẤU HAO DX NHÔM | T8: =SUM(T3:T7)*U8 -> 1505.8009 | U8: 0.05 | V8: =SUM(V3:V7)*U8 -> 268032.55
H9: 06 | I9: Đố động | J9: =CONCATENATE($G$2,"-",$D$11,"-","3323A","-","1") -> --3323A-1 | K9: =ROUNDDOWN(K8-28.2*2-8,0) -> 885 | L9: =G4*1 -> 1 | N9: =N8+1 -> 7 | O9: KE VĨNH CỬU KHUNG BAO - 14*43 | T9: 4 | U9: 4400 | V9: =U9*T9 -> 17600
I10: KÍNH | J10: Ngang | K10: Cao | L10: Số lượng | N10: =N9+1 -> 8 | O10: KE VĨNH CỬU CÁNH - 25*40 | T10: =4*4 -> 16 | U10: 5100 | V10: =U10*T10 -> 81600 | W10: 4 KE VĨNH CỬU 1 CÁNH
J11: =IF(K7-120>0,K7-120,"0") -> 753 | K11: =IF(K8-120>0,K8-120,"0") -> 830 | L11: =G4*4 -> 4 | N11: =N10+1 -> 9 | O11: KE TĂNG CỨNG | T11: =T10*2+T9 -> 36 | U11: 100 | V11: =U11*T11 -> 3600 | W11: 8 KE TĂNG CỨNG 1 CÁNH
N12: =N11+1 -> 10 | O12: TỔNG CHI PHÍ VẬT LIỆU CHÍNH | V12: =SUM(V3:V11) -> 5731483.6
N13: STT | O13: SẢN PHẨM | R13: MÉT DÀI | S13: SỐ LƯỢNG | U13: ĐƠN GIÁ | V13: THÀNH TIỀN
N14: 1 | O14: RON KHUNG BAO | R14: =R3+R4+R6+R7*2 -> 28509 | S14: 1 | U14: 1000 | V14: =U14*R14*S14/1000 -> 28509
N15: =N14+1 -> 2 | O15: RON KÍNH | R15: =R4*2 -> 29168 | S15: 1 | U15: 1000 | V15: =U15*R15*S15/1000 -> 29168
N16: =N15+1 -> 3 | O16: NHỰA ĐỐ ĐỘNG | S16: 1 | U16: 2500 | V16: =U16*S16 -> 2500 | W16: 1 CẶP CHO 1 CÁNH
N17: =N16+1 -> 4 | O17: ỐC VÍT LIÊN KẾT | S17: 1 | U17: 1000 | V17: =U17*S17 -> 1000
N18: =N17+1 -> 5 | O18: GIẤY ĐÓNG GÓI + PE | S18: 1 | U18: 2000 | V18: =U18*S18 -> 2000
N19: =N18+1 -> 6 | O19: TỔNG CHI PHÍ VẬT TƯ CỬA | V19: =SUM(V14:V18) -> 63177
V20: =V12+V19 -> 5794660.6

Sheet VÁCH KÍNH 55
N1: CHÍ PHÍ
B2: THÔNG TIN CÔNG TRÌNH | I2: KÍCH THƯỚC SẢN XUẤT | N2: STT | O2: SẢN PHẨM | R2: MÉT DÀI | S2: TRỌNG LƯỢNG MD | T2: SỐ LƯỢNG TRỌNG LƯỢNG T | U2: ĐƠN GIÁ | V2: THÀNH TIỀN | W2: GHI CHÚ
E3: W | F3: H | G3: Số lượng | H3: STT | I3: Tên | J3: Mã | K3: Kích thước | L3: Số lượng | N3: 1 | O3: KHUNG BAO ĐỨNG | R3: =K4*L4 -> 854 | S3: 0.802 | T3: =S3*R3 -> 684.908 | U3: 178000 | V3: =U3*T3/1000 -> 121913.62
E4: 940 | F4: 427 | G4: 1 | H4: 01 | I4: Đứng K.B | K4: =F4 -> 427 | L4: 2 | N4: =N3+1 -> 2 | O4: KHUNG BAO NGANG | R4: =K5*L5 -> 1880 | S4: 0.802 | T4: =S4*R4 -> 1507.76 | U4: 178000 | V4: =U4*T4/1000 -> 268381.28
E5: KHẤU HAO | F5: DIỆN TÍCH | G5: SỐ KG | H5: 02 | I5: Ngang K.B | K5: =E4 -> 940 | L5: 2 | N5: =N4+1 -> 3 | O5: NẸP KÍNH | R5: =R3+R4 -> 2734 | S5: 0.271 | T5: =S5*R5 -> 740.914 | U5: 178000 | V5: =U5*T5/1000 -> 131882.69
E6: =G6+T6 -> 3080.2611 | F6: =F4*E4/1000 -> 401.38 | G6: =SUM(T3:T5) -> 2933.582 | H6: 03 | I6: NẸP NỐI | K6: =E4 -> 940 | L6: 1 | N6: =N5+1 -> 4 | O6: KHẤU HAO DX NHÔM | T6: =SUM(T3:T5)*U6 -> 146.6791 | U6: 0.05 | V6: =SUM(V3:V5)*U6 -> 26108.88
H7: 03 | I7: KÍNH | J7: Ngang | K7: Cao | L7: Số lượng | N7: =N6+1 -> 5 | O7: KE KHUNG BAO VÁCH KÍNH 14*51 | T7: 4 | U7: 4200 | V7: =U7*T7 -> 16800 | W7: 4 KE 1 CÁNH
H8: 04 | J8: =K4-75 -> 352 | K8: =K5-75 -> 865 | L8: =G4 -> 1 | N8: =N7+1 -> 6 | O8: KE TĂNG CỨNG | T8: 4 | U8: 100 | V8: =U8*T8 -> 400 | W8: 4 KE TĂNG CỨNG 1 CÁNH
N9: =N8+1 -> 7 | O9: TỔNG CHI PHÍ VẬT LIỆU CHÍNH | V9: =SUM(V3:V8) -> 565486.48
N10: =N9+1 -> 8 | O10: SẢN PHẨM | R10: MÉT DÀI | S10: SỐ LƯỢNG | U10: ĐƠN GIÁ | V10: THÀNH TIỀN
N11: =N10+1 -> 9 | O11: RON KÍNH | R11: =R3+R4*2 -> 4614 | S11: 1 | U11: 1000 | V11: =U11*R11*S11/1000 -> 4614
L12: =F6*300 -> 120414 | N12: =N11+1 -> 10 | O12: ỐC VÍT LIÊN KẾT | S12: 1 | U12: 1000 | V12: =U12*S12 -> 1000
L13: =V15+L12+V27 -> 953708.08 | N13: =N12+1 -> 11 | O13: GIẤY ĐÓNG GÓI + PE | S13: 1 | U13: 2000 | V13: =U13*S13 -> 2000
L14: =L13/F6 -> 2376.0727 | N14: =N13+1 -> 12 | O14: TỔNG CHI PHÍ VẬT TƯ CỬA | V14: =SUM(V11:V13) -> 7614
V15: =V14+V9 -> 573100.48
N16: CHÍ PHÍ
N17: STT | O17: SẢN PHẨM | R17: MÉT DÀI | S17: TRỌNG LƯỢNG MD | T17: SỐ LƯỢNG TRỌNG LƯỢNG T | U17: ĐƠN GIÁ | V17: THÀNH TIỀN | W17: GHI CHÚ
N18: 1 | O18: ĐỐ CHIA PANO | R18: 1000 | S18: 0.802 | T18: =S18*R18 -> 802 | U18: 178000 | V18: =U18*T18/1000 -> 142756
N19: 2 | O19: NẸP KÍNH | R19: =R18*2 -> 2000 | S19: 0.271 | T19: =S19*R19 -> 542 | U19: 178000 | V19: =U19*T19/1000 -> 96476
N20: =N19+1 -> 3 | O20: KHẤU HAO DX NHÔM | S20: =SUM(T18:T20) -> 1411.2 | T20: =SUM(T18:T19)*U20 -> 67.2 | U20: 0.05 | V20: =SUM(V18:V19)*U20 -> 11961.6
N21: =N20+1 -> 4 | O21: TỔNG CHI PHÍ VẬT LIỆU CHÍNH | V21: =SUM(V18:V20) -> 251193.6
N22: =N21+1 -> 5 | O22: SẢN PHẨM | R22: MÉT DÀI | S22: SỐ LƯỢNG | U22: ĐƠN GIÁ | V22: THÀNH TIỀN
N23: =N22+1 -> 6 | O23: RON KÍNH | R23: =R18*2+R19*2 -> 6000 | S23: 1 | U23: 1000 | V23: =U23*R23*S23/1000 -> 6000
N24: =N23+1 -> 7 | O24: ỐC VÍT LIÊN KẾT | S24: 1 | U24: 1000 | V24: =U24*S24 -> 1000
N25: =N24+1 -> 8 | O25: GIẤY ĐÓNG GÓI + PE | S25: 1 | U25: 2000 | V25: =U25*S25 -> 2000
N26: =N25+1 -> 9 | O26: TỔNG CHI PHÍ VẬT TƯ CỬA | V26: =SUM(V23:V25) -> 9000
V27: =V26+V21 -> 260193.6

Sheet ĐI QUAY 1 CÁNH 83
B1: BẢN SẢN XUẤT | N1: CHÍ PHÍ
H2: STT | I2: KÍCH THƯỚC SẢN XUẤT | N2: STT | O2: SẢN PHẨM | R2: MÉT DÀI ( mm ) | S2: TRỌNG LƯỢNG MD | T2: SỐ LƯỢNG TRỌNG LƯỢNG | U2: ĐƠN GIÁ | V2: THÀNH TIỀN | W2: GHI CHÚ
E3: W | F3: H | G3: Số lượng | I3: Tên | J3: Mã | K3: Kích thước | L3: Số lượng | N3: 1 | O3: KHUNG BAO CỬA ĐI | R3: =K4*L4+K5*L5 -> 4900 | S3: 1.621 | T3: =S3*R3 -> 7942.9 | U3: 178000 | V3: =U3*T3/1000 -> 1413836.2
E4: 900 | F4: 2000 | G4: 1 | H4: 01 | I4: Ngang K.B | J4: 8301 | K4: =E4 -> 900 | L4: =G4*1 -> 1 | N4: =N3+1 -> 2 | O4: CÁNH CỬA ĐI | R4: =K6*L6+K7*L7 -> 5550 | S4: 1.604 | T4: =S4*R4 -> 8902.2 | U4: 178000 | V4: =U4*T4/1000 -> 1584591.6
E5: KHẤU HAO | F5: DIỆN TÍCH | G5: SỐ KG | H5: 02 | I5: ĐỨNG K.B | J5: 8301 | K5: =F4 -> 2000 | L5: =G4*2 -> 2 | N5: =N4+1 -> 3 | O5: NẸP KÍNH CÁNH | R5: =R4 -> 5550 | S5: 0.279 | T5: =S5*R5 -> 1548.45 | U5: 178000 | V5: =U5*T5/1000 -> 275624.1
E6: =G6+T7 -> 19647.859 | F6: =F4*E4/1000 -> 1800 | G6: =SUM(T3:T6) -> 18712.247 | H6: 03 | I6: N. Cánh | J6: 8303-8304 | K6: =K4-72-10 -> 818 | L6: =G4*2 -> 2 | N6: =N5+1 -> 4 | O6: ỐP CHÂN CÁNH | R6: =K8*L8 -> 757 | S6: 0.421 | T6: =S6*R6 -> 318.697 | U6: 178000 | V6: =U6*T6/1000 -> 56728.066
F7: HỞ NỀN | G7: ÂM NỀN | H7: 04 | I7: Đ. Cánh | J7: 8303-8304 | K7: =IF(AND(F9="X",G9=""),K5-F8,0)+IF(AND(G9="X",F9=""),K5-G8,0) -> 1957 | L7: 2 | N7: =N6+1 -> 5 | O7: KHẤU HAO DX NHÔM | T7: =SUM(T3:T6)*U7 -> 935.61235 | U7: 0.05 | V7: =SUM(V3:V6)*U7 -> 166539
F8: 43 | G8: 23 | H8: 05 | I8: Ốp dưới | J8: 8309 | K8: =K6-61 -> 757 | L8: =G4*1 -> 1 | N8: =N7+1 -> 6 | O8: KE KHUNG BAO | T8: 2 | U8: 25000 | V8: =U8*T8 -> 50000
F9: X | H9: 06 | I9: Kính | J9: Ngang | K9: Cao | L9: Số lượng | N9: =N8+1 -> 7 | O9: KE CÁNH - 40*46,5 | T9: 4 | U9: 18000 | V9: =U9*T9 -> 72000
H10: 07 | J10: =K6-172 -> 646 | K10: =K7-172 -> 1785 | L10: 1 | N10: =N9+1 -> 8 | O10: KE TĂNG CỨNG | T10: =T9*2+T8 -> 10 | U10: 1600 | V10: =U10*T10 -> 16000
N11: =N10+1 -> 9 | O11: TỔNG CHI PHÍ VẬT LIỆU CHÍNH | V11: =SUM(V3:V10) -> 3635319
N12: STT | O12: SẢN PHẨM | R12: MÉT DÀI | S12: SỐ LƯỢNG | U12: ĐƠN GIÁ | V12: THÀNH TIỀN
N13: 1 | O13: RON KHUNG BAO | R13: =R3+R4 -> 10450 | S13: 1 | U13: 1000 | V13: =U13*R13*S13/1000 -> 10450
N14: =N13+1 -> 2 | O14: RON KÍNH | R14: =R4*2 -> 11100 | S14: 1 | U14: 1000 | V14: =U14*R14*S14/1000 -> 11100
N15: =N14+1 -> 3 | O15: NHỰA ỐP CHÂN | S15: 1 | U15: 9500 | V15: =U15*S15 -> 9500 | W15: 1 CẶP CHO 1 CÁNH
N16: =N15+1 -> 4 | O16: ỐC VÍT LIÊN KẾT | S16: 1 | U16: 1000 | V16: =U16*S16 -> 1000 | W16: 1 BỘ
N17: =N16+1 -> 5 | O17: GIẤY ĐÓNG GÓI + PE | S17: 1 | U17: 2000 | V17: =U17*S17 -> 2000 | W17: 1 BỘ
N18: =N17+1 -> 6 | O18: TỔNG CHI PHÍ VẬT TƯ CỬA | V18: =SUM(V13:V17) -> 34050
V19: =V11+V18 -> 3669369
H20: =F20 -> 0

Sheet ĐI QUAY 2 CÁNH 83 
B1: BẢN SẢN XUẤT | N1: CHÍ PHÍ
H2: STT | I2: KÍCH THƯỚC SẢN XUẤT | N2: STT | O2: SẢN PHẨM | R2: MÉT DÀI | S2: TRỌNG LƯỢNG MD | T2: SỐ LƯỢNG TRỌNG LƯỢNG T | U2: ĐƠN GIÁ | V2: THÀNH TIỀN | W2: GHI CHÚ
E3: W | F3: H | G3: Số lượng | I3: Tên | J3: Mã | K3: Kích thước | L3: Số lượng | N3: 1 | O3: KHUNG BAO CỬA ĐI | R3: =K4*L4+K5*L5 -> 5800 | S3: 1.621 | T3: =S3*R3 -> 9401.8 | U3: 178000 | V3: =U3*T3/1000 -> 1673520.4
E4: 1800 | F4: 2000 | G4: 1 | H4: 1 | I4: Ngang K.B | J4: 8301 | K4: =E4 -> 1800 | L4: =G4*1 -> 1 | N4: =N3+1 -> 2 | O4: CÁNH CỬA ĐI | R4: =K6*L6+K7*L7 -> 11282 | S4: 1.604 | T4: =S4*R4 -> 18096.328 | U4: 178000 | V4: =U4*T4/1000 -> 3221146.4
E5: KHẤU HAO | F5: DIỆN TÍCH | G5: SỐ KG | H5: =H4+1 -> 2 | I5: Đứng K.B | J5: 8301 | K5: =F4 -> 2000 | L5: =G4*2 -> 2 | N5: =N4+1 -> 3 | O5: NẸP KÍNH CÁNH | R5: =R4 -> 11282 | S5: 0.279 | T5: =S5*R5 -> 3147.678 | U5: 178000 | V5: =U5*T5/1000 -> 560286.68
E6: =G6+T8 -> 34806.819 | F6: =F4*E4/1000 -> 3600 | G6: =SUM(T3:T7) -> 33149.351 | H6: =H5+1 -> 3 | I6: N/Cánh | J6: 8303-8304 | K6: =(E4-73)/2 -> 863.5 | L6: =G4*4 -> 4 | N6: =N5+1 -> 4 | O6: ỐP CHÂN CÁNH | R6: =K9*L9 -> 1605 | S6: 0.421 | T6: =S6*R6 -> 675.705 | U6: 178000 | V6: =U6*T6/1000 -> 120275.49
F7: HỞ NỀN | G7: ÂM NỀN | H7: =H6+1 -> 4 | I7: Đ/Cánh | J7: 8303-8304 | K7: =IF(AND(F9="X",G9=""),K5-F8,0)+IF(AND(G9="X",F9=""),K5-G8,0) -> 1957 | L7: =G4*4 -> 4 | N7: =N6+1 -> 5 | O7: ĐỐ ĐỘNG | R7: =K8*L8 -> 1904 | S7: 0.96 | T7: =S7*R7 -> 1827.84 | U7: 178000 | V7: =U7*T7/1000 -> 325355.52
F8: 43 | G8: 23 | H8: =H7+1 -> 5 | I8: Đố động | J8: 8306 | K8: =IF(G9="x",ROUNDDOWN(K7-30-4,0),ROUNDDOWN(K7-34-19,0)) -> 1904 | L8: =G4 -> 1 | N8: =N7+1 -> 6 | O8: KHẤU HAO DX NHÔM | T8: =SUM(T3:T7)*U8 -> 1657.4675 | U8: 0.05 | V8: =SUM(V3:V7)*U8 -> 295029.22
F9: X | H9: =H8+1 -> 6 | I9: Nẹp dưới | J9: 8309 | K9: =K6-61 -> 802.5 | L9: =G4*2 -> 2 | N9: =N8+1 -> 7 | O9: KE KHUNG BAO | T9: 2 | U9: 25000 | V9: =U9*T9 -> 50000
H10: =H9+1 -> 7 | I10: Kính | J10: Ngang | K10: Cao | L10: Số lượng | N10: =N9+1 -> 8 | O10: KE CÁNH - 40*46,5 | T10: 8 | U10: 18000 | V10: =U10*T10 -> 144000
H11: =H10+1 -> 8 | J11: =K6-172 -> 691.5 | K11: =K7-172 -> 1785 | L11: =G4*2 -> 2 | N11: =N10+1 -> 9 | O11: KE TĂNG CỨNG | T11: =T10*2+T9 -> 18 | U11: 1600 | V11: =U11*T11 -> 28800
N12: =N11+1 -> 10 | O12: TỔNG CHI PHÍ VẬT LIỆU CHÍNH | V12: =SUM(V3:V11) -> 6418413.7
N13: STT | O13: SẢN PHẨM | R13: MÉT DÀI | S13: SỐ LƯỢNG | U13: ĐƠN GIÁ | V13: THÀNH TIỀN
N14: 1 | O14: RON KHUNG BAO | R14: =R3+R4+R7 -> 18986 | S14: 1 | U14: 1000 | V14: =U14*R14*S14/1000 -> 18986
N15: =N14+1 -> 2 | O15: RON KÍNH | R15: =R4*2 -> 22564 | S15: 1 | U15: 1000 | V15: =U15*R15*S15/1000 -> 22564
N16: =N15+1 -> 3 | O16: NHỰA ỐP CHÂN | S16: 2 | U16: 9500 | V16: =U16*S16 -> 19000 | W16: 1 CẶP CHO 1 CÁNH
N17: =N16+1 -> 4 | O17: NHỰA ĐỐ ĐỘNG | S17: 1 | U17: 10000 | V17: =U17*S17 -> 10000 | W17: 1 CÁI CHO 1 ĐẦU TRÊN
N18: =N17+1 -> 5 | O18: ỐC VÍT LIÊN KẾT | S18: 1 | U18: 1000 | V18: =U18*S18 -> 1000
N19: =N18+1 -> 6 | O19: GIẤY ĐÓNG GÓI + PE | S19: 1 | U19: 2000 | V19: =U19*S19 -> 2000 | W19: 1 BỘ CỬA
N20: =N19+1 -> 7 | O20: TỔNG CHI PHÍ VẬT TƯ CỬA | V20: =SUM(V14:V19) -> 73550
V21: =V12+V20 -> 6491963.7

Sheet ĐI QUAY 4 CÁNH 83
B1: BẢN SẢN XUẤT | N1: CHÍ PHÍ
H2: STT | I2: KÍCH THƯỚC SẢN XUẤT | N2: STT | O2: SẢN PHẨM | R2: MÉT DÀI | S2: TRỌNG LƯỢNG MD | T2: SỐ LƯỢNG TRỌNG LƯỢNG T | U2: ĐƠN GIÁ | V2: THÀNH TIỀN | W2: GHI CHÚ
E3: W | F3: H | G3: Số lượng | I3: Tên | J3: Mã | K3: Kích thước | L3: Số lượng | N3: 1 | O3: KHUNG BAO CỬA ĐI | R3: =K4*L4+K5*L5 -> 7600 | S3: 1.621 | T3: =S3*R3 -> 12319.6 | U3: 178000 | V3: =U3*T3/1000 -> 2192888.8
E4: 3600 | F4: 2000 | G4: 1 | H4: 1 | I4: Ngang K.B | J4: 8301 | K4: =E4 -> 3600 | L4: =G4*1 -> 1 | N4: =N3+1 -> 2 | O4: CÁNH CỬA ĐI | R4: =K6*L6+K7*L7 -> 22682 | S4: 1.604 | T4: =S4*R4 -> 36381.928 | U4: 178000 | V4: =U4*T4/1000 -> 6475983.2
E5: KHẤU HAO | F5: DIỆN TÍCH | G5: SỐ KG | H5: =H4+1 -> 2 | I5: Đứng K.B | J5: 8301 | K5: =F4 -> 2000 | L5: =G4*2 -> 2 | N5: =N4+1 -> 3 | O5: NẸP KÍNH CÁNH | R5: =R4 -> 22682 | S5: 0.279 | T5: =S5*R5 -> 6328.278 | U5: 178000 | V5: =U5*T5/1000 -> 1126433.5
E6: =G6+T8 -> 66063.982 | F6: =F4*E4/1000 -> 7200 | G6: =SUM(T3:T7) -> 62918.078 | H6: =H5+1 -> 3 | I6: N/Cánh | J6: 8303-8304 | K6: =(E4-87)/4 -> 878.25 | L6: =G4*8 -> 8 | N6: =N5+1 -> 4 | O6: ỐP CHÂN CÁNH | R6: =K8*L8 -> 5712 | S6: 0.421 | T6: =S6*R6 -> 2404.752 | U6: 178000 | V6: =U6*T6/1000 -> 428045.86
F7: HỞ NỀN | G7: ÂM NỀN | H7: =H6+1 -> 4 | I7: Đ/Cánh | J7: 8303-8304 | K7: =IF(AND(F9="X",G9=""),K5-F8,0)+IF(AND(G9="X",F9=""),K5-G8,0) -> 1957 | L7: =G4*8 -> 8 | N7: =N6+1 -> 5 | O7: ĐỐ ĐỘNG | R7: =K8*L8 -> 5712 | S7: 0.96 | T7: =S7*R7 -> 5483.52 | U7: 178000 | V7: =U7*T7/1000 -> 976066.56
F8: 43 | G8: 23 | H8: =H7+1 -> 5 | I8: Đố động | J8: 8306 | K8: =IF(G7="x",ROUNDDOWN(K7-30-4,0),ROUNDDOWN(K7-34-19,0)) -> 1904 | L8: =G4*3 -> 3 | N8: =N7+1 -> 6 | O8: KHẤU HAO DX NHÔM | T8: =SUM(T3:T7)*U8 -> 3145.9039 | U8: 0.05 | V8: =SUM(V3:V7)*U8 -> 559970.89
F9: X | H9: =H8+1 -> 6 | I9: Nẹp dưới | J9: 8309 | K9: =K6-61 -> 817.25 | L9: =G4*4 -> 4 | N9: =N8+1 -> 7 | O9: KE KHUNG BAO | T9: 2 | U9: 25000 | V9: =U9*T9 -> 50000
H10: =H9+1 -> 7 | I10: Kính | J10: Ngang | K10: Cao | L10: Số lượng | N10: =N9+1 -> 8 | O10: KE CÁNH - 40*46,5 | T10: 16 | U10: 18000 | V10: =U10*T10 -> 288000 | W10: 4 KE VĨNH CỬU 1 CÁNH
H11: =H10+1 -> 8 | J11: =K6-172 -> 706.25 | K11: =K7-172 -> 1785 | L11: =G4*4 -> 4 | N11: =N10+1 -> 9 | O11: KE TĂNG CỨNG | T11: =T10*2+T9 -> 34 | U11: 1600 | V11: =U11*T11 -> 54400 | W11: 8 KE TĂNG CỨNG 1 CÁNH
N12: =N11+1 -> 10 | O12: TỔNG CHI PHÍ VẬT LIỆU CHÍNH | V12: =SUM(V3:V11) -> 12151789
N13: STT | O13: SẢN PHẨM | R13: MÉT DÀI | S13: SỐ LƯỢNG | U13: ĐƠN GIÁ | V13: THÀNH TIỀN
N14: 1 | O14: RON KHUNG BAO | R14: =R3+R4+R7 -> 35994 | S14: 1 | U14: 1000 | V14: =U14*R14*S14/1000 -> 35994
N15: =N14+1 -> 2 | O15: RON KÍNH | R15: =R4*2 -> 45364 | S15: 1 | U15: 1000 | V15: =U15*R15*S15/1000 -> 45364 | W15: 1 CẶP CHO 1 CÁNH
N16: =N15+1 -> 3 | O16: NHỰA ỐP CHÂN | S16: 4 | U16: 9500 | V16: =U16*S16 -> 38000 | W16: 1 CÁI CHO 1 ĐẦU TRÊN
N17: =N16+1 -> 4 | O17: NHỰA ĐỐ ĐỘNG | S17: 3 | U17: 10000 | V17: =U17*S17 -> 30000
N18: =N17+1 -> 5 | O18: ỐC VÍT LIÊN KẾT | S18: 1 | U18: 1000 | V18: =U18*S18 -> 1000 | W18: 1 BỘ CỬA
N19: =N18+1 -> 6 | O19: GIẤY ĐÓNG GÓI + PE | S19: 1 | U19: 2000 | V19: =U19*S19 -> 2000 | W19: 1 BỘ CỬA
N20: =N19+1 -> 7 | O20: TỔNG CHI PHÍ VẬT TƯ CỬA | V20: =SUM(V14:V19) -> 152358
H21: =F21 -> 0 | V21: =V12+V20 -> 12304147

Sheet SỔ QUAY 1 CÁNH 83
B1: BẢN SẢN XUẤT | N1: CHÍ PHÍ
H2: STT | I2: KÍCH THƯỚC SẢN XUẤT | N2: STT | O2: SẢN PHẨM | R2: MÉT DÀI | S2: TRỌNG LƯỢNG MD | T2: SỐ LƯỢNG TRỌNG LƯỢNG T | U2: ĐƠN GIÁ | V2: THÀNH TIỀN | W2: GHI CHÚ
E3: W | F3: H | G3: Số lượng | I3: Tên | J3: Mã | K3: Kích thước | L3: Số lượng | N3: 1 | O3: KHUNG BAO CỬA SỔ | R3: =K4*L4+K5*L5 -> 3600 | S3: 1.259 | T3: =S3*R3 -> 4532.4 | U3: 178000 | V3: =U3*T3/1000 -> 806767.2
E4: 800 | F4: 1000 | G4: 1 | H4: 01 | I4: Ngang K.B | J4: 8301A | K4: =E4 -> 800 | L4: =G4*2 -> 2 | N4: =N3+1 -> 2 | O4: CÁNH CỬA SỔ | R4: =K6*L6+K7*L7 -> 3336 | S4: 1.051 | T4: =S4*R4 -> 3506.136 | U4: 178000 | V4: =U4*T4/1000 -> 624092.21
E5: KHẤU HAO | F5: DIỆN TÍCH | G5: SỐ KG | H5: 02 | I5: Đứng K.B | J5: 8301A | K5: =F4 -> 1000 | L5: =G4*2 -> 2 | N5: =N4+1 -> 3 | O5: NẸP KÍNH CÁNH | R5: =R4 -> 3336 | S5: 0.279 | T5: =S5*R5 -> 930.744 | U5: 178000 | V5: =U5*T5/1000 -> 165672.43
E6: =G6+T6 -> 9417.744 | F6: =F4*E4/1000 -> 800 | G6: =SUM(T3:T5) -> 8969.28 | H6: 03 | I6: N. Cánh | J6: 8305 | K6: =E4-66 -> 734 | L6: =G4*2 -> 2 | N6: =N5+1 -> 4 | O6: KHẤU HAO DX NHÔM | T6: =SUM(T3:T5)*U6 -> 448.464 | U6: 0.05 | V6: =SUM(V3:V5)*U6 -> 79826.592
H7: 04 | I7: Đ. Cánh | J7: 8305 | K7: =F4-66 -> 934 | L7: =G4*2 -> 2 | N7: =N6+1 -> 5 | O7: KE KHUNG BAO 21*46 | T7: 4 | U7: 18000 | V7: =U7*T7 -> 72000
H8: 05 | I8: KÍNH | J8: Ngang | K8: Cao | L8: Số lượng | N8: =N7+1 -> 6 | O8: KE CÁNH 21*46 | T8: 4 | U8: 18000 | V8: =U8*T8 -> 72000
H9: 06 | J9: =K6-124 -> 610 | K9: =K7-124 -> 810 | L9: =G4 -> 1 | N9: =N8+1 -> 7 | O9: KE TĂNG CỨNG | T9: =T8*2+T7 -> 12 | U9: 1600 | V9: =U9*T9 -> 19200
N10: =N9+1 -> 8 | O10: TỔNG CHI PHÍ VẬT LIỆU CHÍNH | V10: =SUM(V3:V9) -> 1839558.4
N11: STT | O11: SẢN PHẨM | R11: MÉT DÀI | S11: SỐ LƯỢNG | U11: ĐƠN GIÁ | V11: THÀNH TIỀN
N12: 1 | O12: RON KHUNG BAO | R12: =R3+R4 -> 6936 | S12: 1 | U12: 1000 | V12: =U12*R12*S12/1000 -> 6936
N13: =N12+1 -> 2 | O13: RON KÍNH | R13: =R4*2 -> 6672 | S13: 1 | U13: 1000 | V13: =U13*R13*S13/1000 -> 6672
N14: =N13+1 -> 3 | O14: ỐC VÍT LIÊN KẾT | S14: 1 | U14: 1000 | V14: =U14*S14 -> 1000 | W14: 1 BỘ
N15: =N14+1 -> 4 | O15: GIẤY ĐÓNG GÓI + PE | S15: 1 | U15: 2000 | V15: =U15*S15 -> 2000 | W15: 1 BỘ
N16: =N15+1 -> 5 | O16: TỔNG CHI PHÍ VẬT TƯ CỬA | V16: =SUM(V12:V15) -> 16608
V17: =V10+V16 -> 1856166.4

Sheet SỔ QUAY 2 CÁNH 83 
B1: BẢN SẢN XUẤT | N1: CHÍ PHÍ
B2: THÔNG TIN CÔNG TRÌNH | I2: KÍCH THƯỚC SẢN XUẤT | N2: STT | O2: SẢN PHẨM | R2: MÉT DÀI | S2: TRỌNG LƯỢNG MD | T2: SỐ LƯỢNG TRỌNG LƯỢNG T | U2: ĐƠN GIÁ | V2: THÀNH TIỀN | W2: GHI CHÚ
E3: W | F3: H | G3: Số lượng | H3: STT | I3: Tên | J3: Mã | K3: Kích thước | L3: Số lượng | N3: 1 | O3: KHUNG BAO CỬA SỔ | R3: =K4*L4+K5*L5 -> 5600 | S3: 1.259 | T3: =S3*R3 -> 7050.4 | U3: 178000 | V3: =U3*T3/1000 -> 1254971.2
E4: 1800 | F4: 1000 | G4: 1 | H4: 1 | I4: Ngang K.B | J4: 8301A | K4: =E4 -> 1800 | L4: =G4*2 -> 2 | N4: =N3+1 -> 2 | O4: CÁNH CỬA SỔ | R4: =K6*L6+K7*L7 -> 7190 | S4: 1.051 | T4: =S4*R4 -> 7556.69 | U4: 178000 | V4: =U4*T4/1000 -> 1345090.8
E5: KHẤU HAO | F5: DIỆN TÍCH | G5: SỐ KG | H5: =H4+1 -> 2 | I5: Đứng K.B | J5: 8301A | K5: =F4 -> 1000 | L5: =G4*2 -> 2 | N5: =N4+1 -> 3 | O5: NẸP KÍNH CÁNH | R5: =R4 -> 7190 | S5: 0.279 | T5: =S5*R5 -> 2006.01 | U5: 178000 | V5: =U5*T5/1000 -> 357069.78
E6: =G6+T7 -> 18321.723 | F6: =F4*E4/1000 -> 1800 | G6: =SUM(T3:T6) -> 17449.26 | H6: =H5+1 -> 3 | I6: N/Cánh | J6: 8305 | K6: =(E4-73)/2 -> 863.5 | L6: =G4*4 -> 4 | N6: =N5+1 -> 4 | O6: ĐỐ ĐỘNG | R6: =K8*L8 -> 871 | S6: 0.96 | T6: =S6*R6 -> 836.16 | U6: 178000 | V6: =U6*T6/1000 -> 148836.48
H7: =H6+1 -> 4 | I7: Đ/Cánh | J7: 8305 | K7: =F4-66 -> 934 | L7: =G4*4 -> 4 | N7: =N6+1 -> 5 | O7: KHẤU HAO DX NHÔM | T7: =SUM(T3:T6)*U7 -> 872.463 | U7: 0.05 | V7: =SUM(V3:V6)*U7 -> 155298.41
H8: =H7+1 -> 5 | I8: Đố động | J8: 8306 | K8: =K7-63 -> 871 | L8: =G4*1 -> 1 | N8: =N7+1 -> 6 | O8: KE KHUNG BAO 21*46 | T8: 4 | U8: 18000 | V8: =U8*T8 -> 72000
H9: =H8+1 -> 6 | I9: KÍNH | J9: Ngang | K9: Cao | L9: Số lượng | N9: =N8+1 -> 7 | O9: KE CÁNH 21*46 | T9: 8 | U9: 18000 | V9: =U9*T9 -> 144000
H10: =H9+1 -> 7 | J10: =K6-124 -> 739.5 | K10: =K7-124 -> 810 | L10: =G4*2 -> 2 | N10: =N9+1 -> 8 | O10: KE TĂNG CỨNG | T10: =T9*2+T8 -> 20 | U10: 1600 | V10: =U10*T10 -> 32000
N11: =N10+1 -> 9 | O11: TỔNG CHI PHÍ VẬT LIỆU CHÍNH | V11: =SUM(V3:V10) -> 3509266.7
N12: STT | O12: SẢN PHẨM | R12: MÉT DÀI | S12: SỐ LƯỢNG | U12: ĐƠN GIÁ | V12: THÀNH TIỀN
N13: 1 | O13: RON KHUNG BAO | R13: =R3+R4+R6 -> 13661 | S13: 1 | U13: 1000 | V13: =U13*R13*S13/1000 -> 13661
N14: =N13+1 -> 2 | O14: RON KÍNH | R14: =R4*2 -> 14380 | S14: 1 | U14: 1000 | V14: =U14*R14*S14/1000 -> 14380
N15: =N14+1 -> 3 | O15: NHỰA ĐỐ ĐỘNG | S15: 1 | U15: 10000 | V15: =U15*S15 -> 10000 | W15: 1 CẶP
N16: =N15+1 -> 4 | O16: ỐC VÍT LIÊN KẾT | S16: 1 | U16: 1000 | V16: =U16*S16 -> 1000 | W16: 1 BỘ
N17: =N16+1 -> 5 | O17: GIẤY ĐÓNG GÓI + PE | S17: 1 | U17: 2000 | V17: =U17*S17 -> 2000 | W17: 1 BỘ
B18: ` | N18: =N17+1 -> 6 | O18: TỔNG CHI PHÍ VẬT TƯ CỬA | V18: =SUM(V13:V17) -> 41041
V19: =V11+V18 -> 3550307.7

Sheet SỔ QUAY 3 CÁNH 83
B1: BẢN SẢN XUẤT | N1: CHÍ PHÍ
B2: THÔNG TIN CÔNG TRÌNH | I2: KÍCH THƯỚC SẢN XUẤT | N2: STT | O2: SẢN PHẨM | R2: MÉT DÀI | S2: TRỌNG LƯỢNG MD | T2: SỐ LƯỢNG TRỌNG LƯỢNG T | U2: ĐƠN GIÁ | V2: THÀNH TIỀN | W2: GHI CHÚ
E3: W | F3: H | G3: Số lượng | H3: STT | I3: Tên | J3: Mã | K3: Kích thước | L3: Số lượng | N3: 1 | O3: KHUNG BAO CỬA SỔ | R3: =K4*L4+K5*L5 -> 6800 | S3: 1.259 | T3: =S3*R3 -> 8561.2 | U3: 178000 | V3: =U3*T3/1000 -> 1523893.6
E4: 2400 | F4: 1000 | G4: 1 | H4: 01 | I4: Ngang K.B | J4: 8301A | K4: =E4 -> 2400 | L4: =G4*2 -> 2 | N4: =N3+1 -> 2 | O4: CÁNH CỬA SỔ | R4: =K6*L6+K7*L7 -> 10192 | S4: 1.051 | T4: =S4*R4 -> 10711.792 | U4: 178000 | V4: =U4*T4/1000 -> 1906699
E5: KHẤU HAO | F5: DIỆN TÍCH | G5: SỐ KG | H5: 02 | I5: Đứng K.B | J5: 8301A | K5: =F4 -> 1000 | L5: =G4*2 -> 2 | N5: =N4+1 -> 3 | O5: NẸP KÍNH CÁNH | R5: =R4 -> 10192 | S5: 0.279 | T5: =S5*R5 -> 2843.568 | U5: 178000 | V5: =U5*T5/1000 -> 506155.1
E6: =G6+T7 -> 26028.849 | F6: =F4*E4/1000 -> 2400 | G6: =SUM(T3:T6) -> 24789.38 | H6: 03 | I6: N/Cánh | J6: 8305 | K6: =(E4-106)/3 -> 764.66667 | L6: =G4*6 -> 6 | N6: =N5+1 -> 4 | O6: ĐỐ TĨNH | R6: =K8*L8 -> 1860 | S6: 1.437 | T6: =S6*R6 -> 2672.82 | U6: 178000 | V6: =U6*T6/1000 -> 475761.96
H7: 04 | I7: Đ/Cánh | J7: 8305 | K7: =F4-66 -> 934 | L7: =G4*6 -> 6 | N7: =N6+1 -> 5 | O7: KHẤU HAO DX NHÔM | T7: =SUM(T3:T6)*U7 -> 1239.469 | U7: 0.05 | V7: =SUM(V3:V6)*U7 -> 220625.48
H8: 05 | I8: Đố tĩnh | J8: 8307 | K8: =F4-70 -> 930 | L8: =G4*2 -> 2 | N8: =N7+1 -> 6 | O8: KE KHUNG BAO 21*46 | T8: 4 | U8: 18000 | V8: =U8*T8 -> 72000
I9: KÍNH | J9: Ngang | K9: Cao | L9: Số lượng | N9: =N8+1 -> 7 | O9: KE CÁNH 21*46 | T9: 12 | U9: 18000 | V9: =U9*T9 -> 216000 | W9: 4 KE VĨNH CỬU 1 CÁNH
J10: =K6-124 -> 640.66667 | K10: =K7-124 -> 810 | L10: =G4*3 -> 3 | N10: =N9+1 -> 8 | O10: KE TĂNG CỨNG | T10: =T9*2+T8 -> 28 | U10: 1600 | V10: =U10*T10 -> 44800 | W10: 8 KE TĂNG CỨNG 1 CÁNH
N11: =N10+1 -> 9 | O11: TỔNG CHI PHÍ VẬT LIỆU CHÍNH | V11: =SUM(V3:V10) -> 4965935.1
N12: STT | O12: SẢN PHẨM | R12: MÉT DÀI | S12: SỐ LƯỢNG | U12: ĐƠN GIÁ | V12: THÀNH TIỀN
N13: 1 | O13: RON KHUNG BAO | R13: =R3+R6+R4 -> 18852 | S13: 1 | U13: 1000 | V13: =U13*R13/1000 -> 18852
N14: =N13+1 -> 2 | O14: RON KÍNH | R14: =R4*2 -> 20384 | S14: 1 | U14: 1000 | V14: =U14*R14/1000 -> 20384
N15: 3 | O15: ỐC VÍT LIÊN KẾT | S15: 1 | U15: 1000 | V15: =U15*S15 -> 1000 | W15: 1 BỘ
N16: =N15+1 -> 4 | O16: GIẤY ĐÓNG GÓI + PE | S16: 1 | U16: 2000 | V16: =U16*S16 -> 2000 | W16: 1 BỘ
N17: =N16+1 -> 5 | O17: TỔNG CHI PHÍ VẬT TƯ CỬA | V17: =SUM(V13:V16) -> 42236
V18: =V11+V17 -> 5008171.1
W19: `

Sheet SỔ QUAY 4 CÁNH 83
B1: BẢN SẢN XUẤT | N1: CHÍ PHÍ
I2: KÍCH THƯỚC SẢN XUẤT | N2: STT | O2: SẢN PHẨM | R2: MÉT DÀI | S2: TRỌNG LƯỢNG MD | T2: SỐ LƯỢNG TRỌNG LƯỢNG T | U2: ĐƠN GIÁ | V2: THÀNH TIỀN | W2: GHI CHÚ
E3: W | F3: H | G3: Số lượng | H3: STT | I3: Tên | J3: Mã | K3: Kích thước | L3: Số lượng | N3: 1 | O3: KHUNG BAO CỬA SỔ | R3: =K4*L4+K5*L5 -> 9200 | S3: 1.259 | T3: =S3*R3 -> 11582.8 | U3: 178000 | V3: =U3*T3/1000 -> 2061738.4
E4: 3600 | F4: 1000 | G4: 1 | H4: 01 | I4: Ngang K.B | J4: 8301A | K4: =E4 -> 3600 | L4: =G4*2 -> 2 | N4: =N3+1 -> 2 | O4: CÁNH CỬA SỔ | R4: =K7*L7+K8*L8 -> 14446 | S4: 1.051 | T4: =S4*R4 -> 15182.746 | U4: 178000 | V4: =U4*T4/1000 -> 2702528.8
E5: KHẤU HAO | F5: DIỆN TÍCH | G5: SỐ KG | H5: 02 | I5: Đứng K.B | J5: 8301A | K5: =F4 -> 1000 | L5: =G4*2 -> 2 | N5: =N4+1 -> 3 | O5: NẸP KÍNH CÁNH | R5: =R4 -> 14446 | S5: 0.279 | T5: =S5*R5 -> 4030.434 | U5: 178000 | V5: =U5*T5/1000 -> 717417.25
E6: =G6+T8 -> 36018.192 | F6: =F4*E4/1000 -> 3600 | G6: =SUM(T3:T7) -> 34303.04 | H6: 03 | I6: Đố tĩnh | J6: 8307 | K6: =F4-70 -> 930 | L6: =G4*2 -> 2 | N6: =N5+1 -> 4 | O6: ĐỐ ĐỘNG | R6: =K9*L9 -> 869 | S6: 0.96 | T6: =S6*R6 -> 834.24 | U6: 178000 | V6: =U6*T6/1000 -> 148494.72
H7: 04 | I7: N/Cánh | J7: 8305 | K7: =(E4-113)/4 -> 871.75 | L7: =G4*8 -> 8 | N7: =N6+1 -> 5 | O7: ĐỐ TĨNH | R7: =K6*L6 -> 1860 | S7: 1.437 | T7: =S7*R7 -> 2672.82 | U7: 178000 | V7: =U7*T7/1000 -> 475761.96
H8: 05 | I8: Đ/Cánh | J8: 8305 | K8: =F4-66 -> 934 | L8: =G4*8 -> 8 | N8: =N7+1 -> 6 | O8: KHẤU HAO DX NHÔM | T8: =SUM(T3:T7)*U8 -> 1715.152 | U8: 0.05 | V8: =SUM(V3:V7)*U8 -> 305297.06
H9: 06 | I9: Đố động | J9: 8306 | K9: =ROUNDDOWN(K8-28.2*2-8,0) -> 869 | L9: =G4*1 -> 1 | N9: =N8+1 -> 7 | O9: KE KHUNG BAO 21*46 | T9: 4 | U9: 18000 | V9: =U9*T9 -> 72000
I10: KÍNH | J10: Ngang | K10: Cao | L10: Số lượng | N10: =N9+1 -> 8 | O10: KE CÁNH 21*46 | T10: 16 | U10: 18000 | V10: =U10*T10 -> 288000 | W10: 4 KE VĨNH CỬU 1 CÁNH
J11: =K7-124 -> 747.75 | K11: =K8-124 -> 810 | L11: =G4*4 -> 4 | N11: =N10+1 -> 9 | O11: KE TĂNG CỨNG | T11: =T10*2+T9 -> 36 | U11: 1600 | V11: =U11*T11 -> 57600 | W11: 8 KE TĂNG CỨNG 1 CÁNH
N12: =N11+1 -> 10 | O12: TỔNG CHI PHÍ VẬT LIỆU CHÍNH | V12: =SUM(V3:V11) -> 6828838.2
N13: STT | O13: SẢN PHẨM | R13: MÉT DÀI | S13: SỐ LƯỢNG | U13: ĐƠN GIÁ | V13: THÀNH TIỀN
N14: 1 | O14: RON KHUNG BAO | R14: =R3+R4+R6+R7*2 -> 28235 | S14: 1 | U14: 1000 | V14: =U14*R14*S14/1000 -> 28235
N15: =N14+1 -> 2 | O15: RON KÍNH | R15: =R4*2 -> 28892 | S15: 1 | U15: 1000 | V15: =U15*R15*S15/1000 -> 28892
N16: =N15+1 -> 3 | O16: NHỰA ĐỐ ĐỘNG | S16: 1 | U16: 10000 | V16: =U16*S16 -> 10000 | W16: 1 CẶP CHO 1 CÁNH
N17: =N16+1 -> 4 | O17: ỐC VÍT LIÊN KẾT | S17: 1 | U17: 1000 | V17: =U17*S17 -> 1000
N18: =N17+1 -> 5 | O18: GIẤY ĐÓNG GÓI + PE | S18: 1 | U18: 2000 | V18: =U18*S18 -> 2000
N19: =N18+1 -> 6 | O19: TỔNG CHI PHÍ VẬT TƯ CỬA | V19: =SUM(V14:V18) -> 70127
V20: =V12+V19 -> 6898965.2

Sheet VÁCH KÍNH 83
N1: CHÍ PHÍ
B2: THÔNG TIN CÔNG TRÌNH | I2: KÍCH THƯỚC SẢN XUẤT | N2: STT | O2: SẢN PHẨM | R2: MÉT DÀI | S2: TRỌNG LƯỢNG MD | T2: SỐ LƯỢNG TRỌNG LƯỢNG T | U2: ĐƠN GIÁ | V2: THÀNH TIỀN | W2: GHI CHÚ
E3: W | F3: H | G3: Số lượng | H3: STT | I3: Tên | J3: Mã | K3: Kích thước | L3: Số lượng | N3: 1 | O3: KHUNG BAO ĐỨNG | R3: =K4*L4 -> 2000 | S3: 1.259 | T3: =S3*R3 -> 2518 | U3: 178000 | V3: =U3*T3/1000 -> 448204
